Workbook
Name Supervisor: Tablas!$B$56:$B$61

Sheet Notas
A1: Caso Nayra retenciones
A2: Fiscalizacion Doc toe - Taquitoe
A3: Grupo Cachina - Hay dos empresas mas Super Bar Sac y Inn house

Sheet Tablas
A2: Tipo de trabajo
A3: R | B3: Registro y analisis
A4: A | B4: Solo analisis
A5: N | B5: No aplica
A7: Llenado de libros
A8: E | B8: Electronico
A9: F | B9: Fisico
A10: N | B10: No aplica
A12: Declaracion de impuestos
A13: Si | B13: Si
A14: No | B14: No
A17: Escala de compras (Por cantidad de registros)
B18: Desde | C18: Hasta
B19: 0 | C19: 100 | D19: 1
B20: 101 | C20: 500 | D20: 2
B21: 501 | C21: 1000 | D21: 3
B22: 1001 | C22: 5000 | D22: 4
B23: 5001 | C23: Mas | D23: 5
A27: DNI | B27: APELLIDOS Y NOMBRES
A28: 48146098 | B28: Aponte Galarza, José luis
A29: 002680267 | B29: Gutiérrez Villegas Yeleydi Niniveth
A30: 74941636 | B30: Soto Taipe, Cristhian Omar
A31: 48708774 | B31: Nuñez Janto, Amelis Melissa
A32: 74486159 | B32: Quispe Yance, Marisol
A33: 48296671 | B33: Martinez Huanca, Anthony Jean Pierre
A34: 48708774 | B34: Nuñez Janto Amelis Melissa
A35: 42806116 | B35: Victor
A36: 46878793 | B36: Wildor
A37: 40924926 | B37: Angela
A38: 40924506 | B38: Alex
... A49: 75003968 | B49: Lorenzo
A50: 76814749 | B50: Mireya
A51: 74033333 | B51: Carmen D.
A52: 46310728 | B52: Surita Melendrez Henry Gusman
A55: DNI | B55: APELLIDOS Y NOMBRES
A56: 48146098 | B56: Aponte Galarza, José luis
A57: 002680267 | B57: Gutiérrez Villegas Yeleydi Niniveth
A58: 74238083 | B58: Yulisa
A59: 74941636 | B59: Soto Taipe, Cristhian Omar
B64: COMPRAS
...

Sheet Valorizacion
A5: Empresa | B5: Razon social | C5: Contador asignado | D5: Manager | E5: Puntos
A6: 20557075969 | B6: IMPORTACIONES TAKANA CAR S.A.C | E6: 50
A7: 20552097824 | B7: MM STORE E.I.R.L. | C7: Wildor | D7: Jose | E7: 49
A8: 20547984588 | B8: AGRO MI PERU FOODS SAC | E8: 47
A9: 20427377475 | B9: RAINFORES TRADING S.A.C. | C9: Nancy | D9: Jose | E9: 46
A10: 20610421823 | B10: JOFRA TOYS EIRL | E10: 42.5
A11: 20608101790 | B11: NAYRA IMPORT EXPORT E.I.R.L | E11: 42.5
A12: 20543957527 | B12: LA PURITA | E12: 42
A13: 20486468913 | B13: PERÚ DATA CONSULT E.I.R.L. | C13: Yeleydi | D13: Gerencia | E13: 37.5
A14: 10101281359 | B14: YULIANA LIBERTAD DEL AGUILA MESCO | E14: 36.5
A15: 20601012872 | B15: NAYRA YULIANA IMPORT E.I.R.L. | E15: 36.5
A16: 20603128541 | B16: CORPORACION GERONIMO S.A.C | E16: 34.5
A17: 20612740802 | B17: PERU Q PRODUCTS GLOBAL BUSINESS | C17: Jhony | D17: Omar | E17: 34
A18: 20610642854 | B18: CALMI CORPORACION S.A.C. | C18: Rocio | D18: Jose | E18: 34
A19: 20606407816 | B19: NOMADS EQUIPMENT S.R.L. | E19: 32
A20: 20556435040 | B20: ECONAIT S.A.C. | E20: 31
A21: 20608390058 | B21: EXIMPORT VALLE DEL NORTE SAC | E21: 29
A22: 20608089102 | B22: RSQ AGRO SAC | E22: 28.5
A23: 20603055617 | B23: SUBDITEX | E23: 28.5
A24: 20607296813 | B24: JVL IMPORT & EXPORT GROUP S.A.C. | E24: 28
A25: 20602055834 | B25: INFUSIONISTA | E25: 28
A26: 20522453111 | B26: HERAUF PERU S.A.C. | E26: 28
A27: 20605225218 | B27: TAQUITOE SAC | E27: 27
A28: 20612022799 | B28: DEBEL INVERSIONES S.A.C. | C28: Jhony | D28: Omar | E28: 26.5
A29: 20611896752 | B29: CASA MEZCAL | E29: 26
A30: 20611871989 | B30: DOMDAY IMPORTACIONES E.I.R.L. | E30: 25.5
A31: 20609359651 | B31: INVERSIONES PIANDA S.A.C. | E31: 25.5
A32: 20610254315 | B32: DMK | E32: 25
A33: 20601658551 | B33: M.J ELEVADORES S.A.C. | E33: 25
A34: 20611125853 | B34: BD & F SAC | E34: 25
A35: 20609108801 | B35: EXPORTACIONES RODRIGUEZ NEIRA SAC | E35: 24.5
A36: 20602118798 | B36: MARCTEX S.A.C. | E36: 24
A37: 20605994840 | B37: ROCOTITOE S.A.C | E37: 24
A38: 20608602187 | B38: DOC TOE SAC | E38: 24
A39: 20610495746 | B39: TRANSPORTE Y SERVICIOS RAFAEL S.A.C. | E39: 23
A40: 20537193761 | B40: FYR INTERNATIONAL GROUP S.A.C | E40: 23
... A45: 20605578528 | B45: PERU INDUSTRI GN S.A.C. | E45: 20.5
A46: 20614514761 | B46: PARAISO VIP SAC | C46: Yeleydi | D46: Gerencia | E46: 19.5
A47: 20606785781 | B47: DISTRIBUIDORA INTEGRAL PERUANA S.A.C. | C47: Carmen D. | D47: Yulisa | E47: 19
A48: 20605731806 | B48: GRUPO FINANCORP S.A.C | E48: 18.5
...

Sheet Empresas
C1: 1 | D1: =+C1+1 -> 2 | E1: =+D1+1 -> 3 | F1: =+E1+1 -> 4 | G1: =+F1+1 -> 5 | H1: =+G1+1 -> 6 | I1: =+H1+1 -> 7 | J1: =+I1+1 -> 8 | K1: =+J1+1 -> 9 | ... CB1: =+CA1+1 -> 78
I2: 1 | J2: =+I2+1 -> 2 | K2: =+J2+1 -> 3 | L2: =+K2+1 -> 4 | M2: =+L2+1 -> 5 | N2: =+M2+1 -> 6 | O2: =+N2+1 -> 7 | P2: =+O2+1 -> 8 | Q2: =+P2+1 -> 9 | ... CB2: =+CA2+1 -> 72
N4: VOLUMEN DE INFORMACION | BF4: LLEVADO DE LIBROS CONTABLES | BR4: DECLARACIONES OBLIGATORIAS
N5: Compras | Q5: Ventas | T5: Caja y bancos | W5: Kardex | Z5: Devengues | AC5: Planillas | AF5: Activo fijo | AI5: Provisiones | AL5: Importaciones | AO5: Exportaciones | AR5: Costo de ventas | AU5: Costo de produccion | AX5: Costo de servicio | BA5: PDB - Llenado
A6: PERIODO | B6: CODIGO I | C6: CODIGO II | D6: RUC | E6: Razon social | F6: Manager | G6: Contador asignado | H6: DNI | I6: Codigo | J6: Corte de contabilidad | K6: Rubro de empresa | L6: Sistema contable | M6: Regimen Tributario | N6: Cant. mov. | O6: Tipo de trabajo | P6: Valor | Q6: Cant. mov. | R6: Tipo de trabajo | S6: Valor | T6: Cant. mov. | U6: Tipo de trabajo | V6: Valor | W6: Cant. mov. | X6: Tipo de trabajo | Y6: Valor | Z6: Cant. mov. | AA6: Tipo de trabajo | AB6: Valor | AC6: Cant. mov. | AD6: Tipo de trabajo | AE6: Valor | AF6: Cant. mov. | AG6: Tipo de trabajo | AH6: Valor | AI6: Cant. mov. | AJ6: Tipo de trabajo | AK6: Valor | AL6: Cant. mov. | AM6: Tipo de trabajo | AN6: Valor | AO6: Cant. mov. | AP6: Tipo de trabajo | AQ6: Valor | AR6: Cant. mov. | AS6: Tipo de trabajo | AT6: Valor | AU6: Cant. mov. | AV6: Tipo de trabajo | AW6: Valor | AX6: Cant. mov. | AY6: Tipo de trabajo | AZ6: Valor | BA6: Cant. mov. | BB6: Tipo de trabajo | BC6: Valor | BD6: x | BE6: Total | BF6: Ventas | BG6: Compras | BH6: Diario | BI6: Diario simpl. | BJ6: Mayor | BK6: Inv. y Bal. | BL6: Libro de retenciones | BM6: Activo fijo | BN6: Costos | BO6: Kardex unid. Fis. | BP6: Kardex valoriz. | BQ6: Total | BR6: PDT 621 | BS6: PDT 601 | BT6: PDT 617 | BU6: PDB | BV6: AFP NET | BW6: PDT 626 | BX6: PDT 633/697 | BY6: PDT 648 | BZ6: PDT 3500 DAOT | CA6: PDT 3560 | CB6: Total | CC6: TOTAL GENERAL | CD6: USUARIO SOL | CE6: CLAVE SOL | CF6: SECTOR
A7: 2026-08 | B7: =A7&D7 -> 2026-0820600133897 | C7: =A7&"|"&G7&"|"&D7 -> 2026-08|Rocio |20600133897 | D7: 20600133897 | E7: A. NAUTICAL - AIR INTL S.A.C. | F7: Jose | G7: Rocio | H7: 42576958 | I7: =CONCATENATE(D7,"|",G7) -> 20600133897|Rocio | J7: Semestral | K7: Servicios | L7: Contaweb | M7: Mype | N7: 180 | O7: R | P7: =IF(O7="N",0,IF(O7="A",VLOOKUP(N7,Tablas!$B$66:$D$69,2),IF(O7="R",VLOOKUP(N7,Tablas!$B$66:$D$69,3)))) -> 2 | Q7: 80 | R7: R | S7: =IF(R7="N",0,IF(R7="A",VLOOKUP(Q7,Tablas!$B$73:$D$76,2),IF(R7="R",VLOOKUP(Q7,Tablas!$B$73:$D$76,3)))) -> 1 | T7: 200 | U7: R | V7: =IF(U7="N",0,IF(U7="A",VLOOKUP(T7,Tablas!$B$80:$D$83,2),IF(U7="R",VLOOKUP(T7,Tablas!$B$80:$D$83,3)))) -> 2 | X7: N | Y7: =IF(X7="N",0,IF(X7="A",VLOOKUP(W7,Tablas!$B$87:$D$90,2),IF(X7="R",VLOOKUP(W7,Tablas!$B$87:$D$90,3)))) -> 0 | AA7: N | AB7: =IF(AA7="N",0,IF(AA7="A",VLOOKUP(Z7,Tablas!$B$143:$D$146,2),IF(AA7="R",VLOOKUP(Z7,Tablas!$B$143:$D$146,3)))) -> 0 | AC7: 5 | AD7: R | AE7: =IF(AD7="N",0,IF(AD7="A",VLOOKUP(AC7,Tablas!$B$101:$D$104,2),IF(AD7="R",VLOOKUP(AC7,Tablas!$B$101:$D$104,3)))) -> 4 | AF7: 4 | AG7: R | AH7: =IF(AG7="N",0,IF(AG7="A",VLOOKUP(AF7,Tablas!$B$94:$D$98,2),IF(AG7="R",VLOOKUP(AF7,Tablas!$B$94:$D$98,3)))) -> 1 | AI7: 1 | AJ7: R | AK7: =IF(AJ7="N",0,IF(AJ7="A",VLOOKUP(AI7,Tablas!$B$150:$D$154,2),IF(AJ7="R",VLOOKUP(AI7,Tablas!$B$150:$D$154,3)))) -> 1 | AM7: N | AN7: =IF(AM7="N",0,IF(AM7="A",VLOOKUP(AL7,Tablas!$B$108:$D$111,2),IF(AM7="R",VLOOKUP(AL7,Tablas!$B$108:$D$111,3)))) -> 0 | AP7: N | AQ7: =IF(AP7="N",0,IF(AP7="A",VLOOKUP(AO7,Tablas!$B$115:$D$118,2),IF(AP7="R",VLOOKUP(AO7,Tablas!$B$115:$D$118,3)))) -> 0 | AS7: N | AT7: =IF(AS7="N",0,IF(AS7="A",VLOOKUP(AR7,Tablas!$B$87:$D$90,2),IF(AS7="R",VLOOKUP(AR7,Tablas!$B$87:$D$90,3)))) -> 0 | AV7: N | AW7: =IF(AV7="N",0,IF(AV7="A",VLOOKUP(AU7,Tablas!$B$129:$D$132,2),IF(AV7="R",VLOOKUP(AU7,Tablas!$B$129:$D$132,3)))) -> 0 | AX7: 50 | AY7: R | AZ7: =IF(AY7="N",0,IF(AY7="A",VLOOKUP(AX7,Tablas!$B$136:$D$139,2),IF(AY7="R",VLOOKUP(AX7,Tablas!$B$136:$D$139,3)))) -> 1 | BB7: N | BC7: =IF(BB7="N",0,IF(BB7="A",VLOOKUP(BA7,Tablas!$B$122:$D$125,2),IF(BB7="R",VLOOKUP(BA7,Tablas!$B$122:$D$125,3)))) -> 0 | BE7: =SUMIF($N$6:$BD$6,"Valor",N7:BD7) -> 12 | BF7: E | BG7: E | BH7: N | BI7: F | BJ7: N | BK7: N | BL7: N | BM7: N | BN7: N | BO7: N | BP7: N | BQ7: =COUNTIF($BF7:$BP7,"E")*2+COUNTIF($BF7:$BP7,"F")*1 -> 5 | BR7: Si | BS7: Si | BT7: No | BU7: No | BV7: Si | BW7: No | BX7: No | BY7: No | BZ7: Si | CA7: No | CB7: =COUNTIF($BR7:$CA7,"SI") -> 4 | CC7: =+BE7+BQ7+CB7 -> 21 | CD7: SANGSWAK | CE7: Nautical2@22 | CF7: D
A8: 2026-08 | B8: =A8&D8 -> 2026-0820547984588 | C8: =A8&"|"&G8&"|"&D8 -> 2026-08|Lorenzo|20547984588 | D8: 20547984588 | E8: AGRO MI PERU FOODS SAC | F8: Yulisa | G8: Lorenzo | H8: 75003968 | I8: =CONCATENATE(D8,"|",G8) -> 20547984588|Lorenzo | J8: Mensual | K8: Comercial - Produccion | L8: Anka | M8: General/Prico | N8: 350 | O8: A | P8: =IF(O8="N",0,IF(O8="A",VLOOKUP(N8,Tablas!$B$66:$D$69,2),IF(O8="R",VLOOKUP(N8,Tablas!$B$66:$D$69,3)))) -> 1 | Q8: 70 | R8: A | S8: =IF(R8="N",0,IF(R8="A",VLOOKUP(Q8,Tablas!$B$73:$D$76,2),IF(R8="R",VLOOKUP(Q8,Tablas!$B$73:$D$76,3)))) -> 0.5 | T8: 700 | U8: A | V8: =IF(U8="N",0,IF(U8="A",VLOOKUP(T8,Tablas!$B$80:$D$83,2),IF(U8="R",VLOOKUP(T8,Tablas!$B$80:$D$83,3)))) -> 1.5 | W8: 500 | X8: A | Y8: =IF(X8="N",0,IF(X8="A",VLOOKUP(W8,Tablas!$B$87:$D$90,2),IF(X8="R",VLOOKUP(W8,Tablas!$B$87:$D$90,3)))) -> 3 | Z8: 10 | AA8: A | AB8: =IF(AA8="N",0,IF(AA8="A",VLOOKUP(Z8,Tablas!$B$143:$D$146,2),IF(AA8="R",VLOOKUP(Z8,Tablas!$B$143:$D$146,3)))) -> 0.5 | AC8: 10 | AD8: R | AE8: =IF(AD8="N",0,IF(AD8="A",VLOOKUP(AC8,Tablas!$B$101:$D$104,2),IF(AD8="R",VLOOKUP(AC8,Tablas!$B$101:$D$104,3)))) -> 6 | AF8: 50 | AG8: A | AH8: =IF(AG8="N",0,IF(AG8="A",VLOOKUP(AF8,Tablas!$B$94:$D$98,2),IF(AG8="R",VLOOKUP(AF8,Tablas!$B$94:$D$98,3)))) -> 0.5 | AI8: 50 | AJ8: R | AK8: =IF(AJ8="N",0,IF(AJ8="A",VLOOKUP(AI8,Tablas!$B$150:$D$154,2),IF(AJ8="R",VLOOKUP(AI8,Tablas!$B$150:$D$154,3)))) -> 1 | AM8: N | AN8: =IF(AM8="N",0,IF(AM8="A",VLOOKUP(AL8,Tablas!$B$108:$D$111,2),IF(AM8="R",VLOOKUP(AL8,Tablas!$B$108:$D$111,3)))) -> 0 | AO8: 8 | AP8: A | AQ8: =IF(AP8="N",0,IF(AP8="A",VLOOKUP(AO8,Tablas!$B$115:$D$118,2),IF(AP8="R",VLOOKUP(AO8,Tablas!$B$115:$D$118,3)))) -> 1 | AR8: =+W8 -> 500 | AS8: =+X8 -> A | AT8: =IF(AS8="N",0,IF(AS8="A",VLOOKUP(AR8,Tablas!$B$87:$D$90,2),IF(AS8="R",VLOOKUP(AR8,Tablas!$B$87:$D$90,3)))) -> 3 | AU8: 200 | AV8: A | AW8: =IF(AV8="N",0,IF(AV8="A",VLOOKUP(AU8,Tablas!$B$129:$D$132,2),IF(AV8="R",VLOOKUP(AU8,Tablas!$B$129:$D$132,3)))) -> 4 | AY8: N | AZ8: =IF(AY8="N",0,IF(AY8="A",VLOOKUP(AX8,Tablas!$B$136:$D$139,2),IF(AY8="R",VLOOKUP(AX8,Tablas!$B$136:$D$139,3)))) -> 0 | BA8: =250+70 -> 320 | BB8: R | BC8: =IF(BB8="N",0,IF(BB8="A",VLOOKUP(BA8,Tablas!$B$122:$D$125,2),IF(BB8="R",VLOOKUP(BA8,Tablas!$B$122:$D$125,3)))) -> 4 | BE8: =SUMIF($N$6:$BD$6,"Valor",N8:BD8) -> 26 | BF8: E | BG8: E | BH8: E | BI8: N | BJ8: E | BK8: F | BL8: N | BM8: F | BN8: F | BO8: F | BP8: F | BQ8: =COUNTIF($BF8:$BP8,"E")*2+COUNTIF($BF8:$BP8,"F")*1 -> 13 | BR8: Si | BS8: Si | BT8: No | BU8: Si | BV8: Si | BW8: Si | BX8: Si | BY8: Si | BZ8: Si | CA8: No | CB8: =COUNTIF($BR8:$CA8,"SI") -> 8 | CC8: =+BE8+BQ8+CB8 -> 47 | CD8: OPASTIVI | CE8: cladbeepi | CF8: A
A9: 2026-08 | B9: =A9&D9 -> 2026-0820609359651 | C9: =A9&"|"&G9&"|"&D9 -> 2026-08|Wildor|20609359651 | D9: 20609359651 | E9: INVERSIONES PIANDA S.A.C. | F9: Jose | G9: Wildor | H9: 46878793 | I9: =CONCATENATE(D9,"|",G9) -> 20609359651|Wildor | J9: Trimestral | K9: Comercial | L9: Anka | M9: General/Prico | N9: 50 | O9: A | P9: =IF(O9="N",0,IF(O9="A",VLOOKUP(N9,Tablas!$B$66:$D$69,2),IF(O9="R",VLOOKUP(N9,Tablas!$B$66:$D$69,3)))) -> 0.5 | Q9: 50 | R9: A | S9: =IF(R9="N",0,IF(R9="A",VLOOKUP(Q9,Tablas!$B$73:$D$76,2),IF(R9="R",VLOOKUP(Q9,Tablas!$B$73:$D$76,3)))) -> 0.5 | T9: 50 | U9: A | V9: =IF(U9="N",0,IF(U9="A",VLOOKUP(T9,Tablas!$B$80:$D$83,2),IF(U9="R",VLOOKUP(T9,Tablas!$B$80:$D$83,3)))) -> 0.5 | W9: 500 | X9: A | Y9: =IF(X9="N",0,IF(X9="A",VLOOKUP(W9,Tablas!$B$87:$D$90,2),IF(X9="R",VLOOKUP(W9,Tablas!$B$87:$D$90,3)))) -> 3 | Z9: 3 | AA9: A | AB9: =IF(AA9="N",0,IF(AA9="A",VLOOKUP(Z9,Tablas!$B$143:$D$146,2),IF(AA9="R",VLOOKUP(Z9,Tablas!$B$143:$D$146,3)))) -> 0.5 | AC9: 4 | AD9: R | AE9: =IF(AD9="N",0,IF(AD9="A",VLOOKUP(AC9,Tablas!$B$101:$D$104,2),IF(AD9="R",VLOOKUP(AC9,Tablas!$B$101:$D$104,3)))) -> 2 | AG9: N | AH9: =IF(AG9="N",0,IF(AG9="A",VLOOKUP(AF9,Tablas!$B$94:$D$98,2),IF(AG9="R",VLOOKUP(AF9,Tablas!$B$94:$D$98,3)))) -> 0 | AI9: 2 | AJ9: A | AK9: =IF(AJ9="N",0,IF(AJ9="A",VLOOKUP(AI9,Tablas!$B$150:$D$154,2),IF(AJ9="R",VLOOKUP(AI9,Tablas!$B$150:$D$154,3)))) -> 0.5 | AL9: 6 | AM9: A | AN9: =IF(AM9="N",0,IF(AM9="A",VLOOKUP(AL9,Tablas!$B$108:$D$111,2),IF(AM9="R",VLOOKUP(AL9,Tablas!$B$108:$D$111,3)))) -> 2 | AP9: N | AQ9: =IF(AP9="N",0,IF(AP9="A",VLOOKUP(AO9,Tablas!$B$115:$D$118,2),IF(AP9="R",VLOOKUP(AO9,Tablas!$B$115:$D$118,3)))) -> 0 | AR9: =+W9 -> 500 | AS9: R | AT9: =IF(AS9="N",0,IF(AS9="A",VLOOKUP(AR9,Tablas!$B$87:$D$90,2),IF(AS9="R",VLOOKUP(AR9,Tablas!$B$87:$D$90,3)))) -> 6 | AV9: N | AW9: =IF(AV9="N",0,IF(AV9="A",VLOOKUP(AU9,Tablas!$B$129:$D$132,2),IF(AV9="R",VLOOKUP(AU9,Tablas!$B$129:$D$132,3)))) -> 0 | AY9: N | AZ9: =IF(AY9="N",0,IF(AY9="A",VLOOKUP(AX9,Tablas!$B$136:$D$139,2),IF(AY9="R",VLOOKUP(AX9,Tablas!$B$136:$D$139,3)))) -> 0 | BB9: N | BC9: =IF(BB9="N",0,IF(BB9="A",VLOOKUP(BA9,Tablas!$B$122:$D$125,2),IF(BB9="R",VLOOKUP(BA9,Tablas!$B$122:$D$125,3)))) -> 0 | BE9: =SUMIF($N$6:$BD$6,"Valor",N9:BD9) -> 15.5 | BF9: E | BG9: E | BH9: N | BI9: F | BJ9: F | BK9: N | BL9: N | BM9: N | BN9: N | BO9: N | BP9: N | BQ9: =COUNTIF($BF9:$BP9,"E")*2+COUNTIF($BF9:$BP9,"F")*1 -> 6 | BR9: Si | BS9: Si | BT9: No | BU9: No | BV9: Si | BW9: No | BX9: No | BY9: No | BZ9: Si | CA9: No | CB9: =COUNTIF($BR9:$CA9,"SI") -> 4 | CC9: =+BE9+BQ9+CB9 -> 25.5 | CD9: MACCAWAL | CE9: allicaryl | CF9: B
A10: 2026-08 | B10: =A10&D10 -> 2026-0820516394138 | C10: =A10&"|"&G10&"|"&D10 -> 2026-08|Lorenzo|20516394138 | D10: 20516394138 | E10: ASESORIA & NEGOCIOS DEL PERU S.A.C. | F10: Yulisa | G10: Lorenzo | H10: 75003968 | I10: =CONCATENATE(D10,"|",G10) -> 20516394138|Lorenzo | J10: Semestral | K10: Comercial | L10: Contaweb | M10: Mype | N10: 70 | O10: R | P10: =IF(O10="N",0,IF(O10="A",VLOOKUP(N10,Tablas!$B$66:$D$69,2),IF(O10="R",VLOOKUP(N10,Tablas!$B$66:$D$69,3)))) -> 1 | Q10: 60 | R10: R | S10: =IF(R10="N",0,IF(R10="A",VLOOKUP(Q10,Tablas!$B$73:$D$76,2),IF(R10="R",VLOOKUP(Q10,Tablas!$B$73:$D$76,3)))) -> 1 | T10: 150 | U10: R | V10: =IF(U10="N",0,IF(U10="A",VLOOKUP(T10,Tablas!$B$80:$D$83,2),IF(U10="R",VLOOKUP(T10,Tablas!$B$80:$D$83,3)))) -> 2 | X10: N | Y10: =IF(X10="N",0,IF(X10="A",VLOOKUP(W10,Tablas!$B$87:$D$90,2),IF(X10="R",VLOOKUP(W10,Tablas!$B$87:$D$90,3)))) -> 0 | AA10: N | AB10: =IF(AA10="N",0,IF(AA10="A",VLOOKUP(Z10,Tablas!$B$143:$D$146,2),IF(AA10="R",VLOOKUP(Z10,Tablas!$B$143:$D$146,3)))) -> 0 | AC10: 2 | AD10: R | AE10: =IF(AD10="N",0,IF(AD10="A",VLOOKUP(AC10,Tablas!$B$101:$D$104,2),IF(AD10="R",VLOOKUP(AC10,Tablas!$B$101:$D$104,3)))) -> 2 | AG10: N | AH10: =IF(AG10="N",0,IF(AG10="A",VLOOKUP(AF10,Tablas!$B$94:$D$98,2),IF(AG10="R",VLOOKUP(AF10,Tablas!$B$94:$D$98,3)))) -> 0 | AJ10: N | AK10: =IF(AJ10="N",0,IF(AJ10="A",VLOOKUP(AI10,Tablas!$B$150:$D$154,2),IF(AJ10="R",VLOOKUP(AI10,Tablas!$B$150:$D$154,3)))) -> 0 | AM10: N | AN10: =IF(AM10="N",0,IF(AM10="A",VLOOKUP(AL10,Tablas!$B$108:$D$111,2),IF(AM10="R",VLOOKUP(AL10,Tablas!$B$108:$D$111,3)))) -> 0 | AP10: N | AQ10: =IF(AP10="N",0,IF(AP10="A",VLOOKUP(AO10,Tablas!$B$115:$D$118,2),IF(AP10="R",VLOOKUP(AO10,Tablas!$B$115:$D$118,3)))) -> 0 | AS10: N | AT10: =IF(AS10="N",0,IF(AS10="A",VLOOKUP(AR10,Tablas!$B$87:$D$90,2),IF(AS10="R",VLOOKUP(AR10,Tablas!$B$87:$D$90,3)))) -> 0 | AV10: N | AW10: =IF(AV10="N",0,IF(AV10="A",VLOOKUP(AU10,Tablas!$B$129:$D$132,2),IF(AV10="R",VLOOKUP(AU10,Tablas!$B$129:$D$132,3)))) -> 0 | AY10: N | AZ10: =IF(AY10="N",0,IF(AY10="A",VLOOKUP(AX10,Tablas!$B$136:$D$139,2),IF(AY10="R",VLOOKUP(AX10,Tablas!$B$136:$D$139,3)))) -> 0 | BB10: N | BC10: =IF(BB10="N",0,IF(BB10="A",VLOOKUP(BA10,Tablas!$B$122:$D$125,2),IF(BB10="R",VLOOKUP(BA10,Tablas!$B$122:$D$125,3)))) -> 0 | BE10: =SUMIF($N$6:$BD$6,"Valor",N10:BD10) -> 6 | BF10: E | BG10: E | BH10: N | BI10: F | BJ10: N | BK10: N | BL10: N | BM10: N | BN10: N | BO10: N | BP10: N | BQ10: =COUNTIF($BF10:$BP10,"E")*2+COUNTIF($BF10:$BP10,"F")*1 -> 5 | BR10: Si | BS10: Si | BT10: No | BU10: No | BV10: Si | BW10: No | BX10: No | BY10: No | BZ10: No | CA10: No | CB10: =COUNTIF($BR10:$CA10,"SI") -> 3 | CC10: =+BE10+BQ10+CB10 -> 14 | CD10: ADWIBCEN | CE10: QR2d1TPaH | CF10: D
A11: 2026-08 | B11: =A11&D11 -> 2026-0820556435040 | C11: =A11&"|"&G11&"|"&D11 -> 2026-08|Marisol|20556435040 | D11: 20556435040 | E11: ECONAIT S.A.C. | F11: Omar | G11: Marisol | H11: 74486159 | I11: =CONCATENATE(D11,"|",G11) -> 20556435040|Marisol | J11: Mensual | K11: Bares - Restaurantes | L11: Anka | M11: General | N11: 300 | O11: R | P11: =IF(O11="N",0,IF(O11="A",VLOOKUP(N11,Tablas!$B$66:$D$69,2),IF(O11="R",VLOOKUP(N11,Tablas!$B$66:$D$69,3)))) -> 2 | Q11: 8000 | R11: R | S11: =IF(R11="N",0,IF(R11="A",VLOOKUP(Q11,Tablas!$B$73:$D$76,2),IF(R11="R",VLOOKUP(Q11,Tablas!$B$73:$D$76,3)))) -> 4 | T11: 500 | U11: R | V11: =IF(U11="N",0,IF(U11="A",VLOOKUP(T11,Tablas!$B$80:$D$83,2),IF(U11="R",VLOOKUP(T11,Tablas!$B$80:$D$83,3)))) -> 3 | X11: N | Y11: =IF(X11="N",0,IF(X11="A",VLOOKUP(W11,Tablas!$B$87:$D$90,2),IF(X11="R",VLOOKUP(W11,Tablas!$B$87:$D$90,3)))) -> 0 | Z11: 2 | AA11: R | AB11: =IF(AA11="N",0,IF(AA11="A",VLOOKUP(Z11,Tablas!$B$143:$D$146,2),IF(AA11="R",VLOOKUP(Z11,Tablas!$B$143:$D$146,3)))) -> 1 | AC11: 9 | AD11: R | AE11: =IF(AD11="N",0,IF(AD11="A",VLOOKUP(AC11,Tablas!$B$101:$D$104,2),IF(AD11="R",VLOOKUP(AC11,Tablas!$B$101:$D$104,3)))) -> 4 | AF11: 45 | AG11: R | AH11: =IF(AG11="N",0,IF(AG11="A",VLOOKUP(AF11,Tablas!$B$94:$D$98,2),IF(AG11="R",VLOOKUP(AF11,Tablas!$B$94:$D$98,3)))) -> 1 | AI11: 1 | AJ11: R | AK11: =IF(AJ11="N",0,IF(AJ11="A",VLOOKUP(AI11,Tablas!$B$150:$D$154,2),IF(AJ11="R",VLOOKUP(AI11,Tablas!$B$150:$D$154,3)))) -> 1 | AM11: N | AN11: =IF(AM11="N",0,IF(AM11="A",VLOOKUP(AL11,Tablas!$B$108:$D$111,2),IF(AM11="R",VLOOKUP(AL11,Tablas!$B$108:$D$111,3)))) -> 0 | AP11: N | AQ11: =IF(AP11="N",0,IF(AP11="A",VLOOKUP(AO11,Tablas!$B$115:$D$118,2),IF(AP11="R",VLOOKUP(AO11,Tablas!$B$115:$D$118,3)))) -> 0 | AR11: 12 | AS11: R | AT11: =IF(AS11="N",0,IF(AS11="A",VLOOKUP(AR11,Tablas!$B$87:$D$90,2),IF(AS11="R",VLOOKUP(AR11,Tablas!$B$87:$D$90,3)))) -> 2 | AV11: N | AW11: =IF(AV11="N",0,IF(AV11="A",VLOOKUP(AU11,Tablas!$B$129:$D$132,2),IF(AV11="R",VLOOKUP(AU11,Tablas!$B$129:$D$132,3)))) -> 0 | AY11: N | AZ11: =IF(AY11="N",0,IF(AY11="A",VLOOKUP(AX11,Tablas!$B$136:$D$139,2),IF(AY11="R",VLOOKUP(AX11,Tablas!$B$136:$D$139,3)))) -> 0 | BB11: N | BC11: =IF(BB11="N",0,IF(BB11="A",VLOOKUP(BA11,Tablas!$B$122:$D$125,2),IF(BB11="R",VLOOKUP(BA11,Tablas!$B$122:$D$125,3)))) -> 0 | BE11: =SUMIF($N$6:$BD$6,"Valor",N11:BD11) -> 18 | BF11: E | BG11: E | BH11: F | BI11: N | BJ11: F | BK11: F | BL11: N | BM11: F | BN11: N | BO11: N | BP11: F | BQ11: =COUNTIF($BF11:$BP11,"E")*2+COUNTIF($BF11:$BP11,"F")*1 -> 9 | BR11: Si | BS11: Si | BT11: No | BU11: No | BV11: Si | BW11: No | BX11: No | BY11: Si | BZ11: No | CA11: No | CB11: =COUNTIF($BR11:$CA11,"SI") -> 4 | CC11: =+BE11+BQ11+CB11 -> 31 | CD11: RONELLBE | CE11: aptonlade | CF11: A
A12: 2026-08 | B12: =A12&D12 -> 2026-0820608390058 | C12: =A12&"|"&G12&"|"&D12 -> 2026-08|Lorenzo|20608390058 | D12: 20608390058 | E12: EXIMPORT VALLE DEL NORTE SAC | F12: Yulisa | G12: Lorenzo | H12: 75003968 | I12: =CONCATENATE(D12,"|",G12) -> 20608390058|Lorenzo | J12: Trimestral | K12: Comercial | L12: Anka | M12: Mype | N12: 20 | O12: R | P12: =IF(O12="N",0,IF(O12="A",VLOOKUP(N12,Tablas!$B$66:$D$69,2),IF(O12="R",VLOOKUP(N12,Tablas!$B$66:$D$69,3)))) -> 1 | Q12: 5 | R12: R | S12: =IF(R12="N",0,IF(R12="A",VLOOKUP(Q12,Tablas!$B$73:$D$76,2),IF(R12="R",VLOOKUP(Q12,Tablas!$B$73:$D$76,3)))) -> 1 | T12: 50 | U12: R | V12: =IF(U12="N",0,IF(U12="A",VLOOKUP(T12,Tablas!$B$80:$D$83,2),IF(U12="R",VLOOKUP(T12,Tablas!$B$80:$D$83,3)))) -> 1 | W12: 50 | X12: R | Y12: =IF(X12="N",0,IF(X12="A",VLOOKUP(W12,Tablas!$B$87:$D$90,2),IF(X12="R",VLOOKUP(W12,Tablas!$B$87:$D$90,3)))) -> 2 | AA12: N | AB12: =IF(AA12="N",0,IF(AA12="A",VLOOKUP(Z12,Tablas!$B$143:$D$146,2),IF(AA12="R",VLOOKUP(Z12,Tablas!$B$143:$D$146,3)))) -> 0 | AC12: 1 | AD12: R | AE12: =IF(AD12="N",0,IF(AD12="A",VLOOKUP(AC12,Tablas!$B$101:$D$104,2),IF(AD12="R",VLOOKUP(AC12,Tablas!$B$101:$D$104,3)))) -> 2 | AF12: 2 | AG12: R | AH12: =IF(AG12="N",0,IF(AG12="A",VLOOKUP(AF12,Tablas!$B$94:$D$98,2),IF(AG12="R",VLOOKUP(AF12,Tablas!$B$94:$D$98,3)))) -> 1 | AI12: 1 | AJ12: R | AK12: =IF(AJ12="N",0,IF(AJ12="A",VLOOKUP(AI12,Tablas!$B$150:$D$154,2),IF(AJ12="R",VLOOKUP(AI12,Tablas!$B$150:$D$154,3)))) -> 1 | AM12: N | AN12: =IF(AM12="N",0,IF(AM12="A",VLOOKUP(AL12,Tablas!$B$108:$D$111,2),IF(AM12="R",VLOOKUP(AL12,Tablas!$B$108:$D$111,3)))) -> 0 | AO12: 5 | AP12: R | AQ12: =IF(AP12="N",0,IF(AP12="A",VLOOKUP(AO12,Tablas!$B$115:$D$118,2),IF(AP12="R",VLOOKUP(AO12,Tablas!$B$115:$D$118,3)))) -> 2 | AR12: =+W12 -> 50 | AS12: =+X12 -> R | AT12: =IF(AS12="N",0,IF(AS12="A",VLOOKUP(AR12,Tablas!$B$87:$D$90,2),IF(AS12="R",VLOOKUP(AR12,Tablas!$B$87:$D$90,3)))) -> 2 | AV12: N | AW12: =IF(AV12="N",0,IF(AV12="A",VLOOKUP(AU12,Tablas!$B$129:$D$132,2),IF(AV12="R",VLOOKUP(AU12,Tablas!$B$129:$D$132,3)))) -> 0 | AY12: N | AZ12: =IF(AY12="N",0,IF(AY12="A",VLOOKUP(AX12,Tablas!$B$136:$D$139,2),IF(AY12="R",VLOOKUP(AX12,Tablas!$B$136:$D$139,3)))) -> 0 | BA12: 25 | BB12: R | BC12: =IF(BB12="N",0,IF(BB12="A",VLOOKUP(BA12,Tablas!$B$122:$D$125,2),IF(BB12="R",VLOOKUP(BA12,Tablas!$B$122:$D$125,3)))) -> 2 | BE12: =SUMIF($N$6:$BD$6,"Valor",N12:BD12) -> 15 | BF12: E | BG12: E | BH12: F | BI12: N | BJ12: F | BK12: F | BL12: N | BM12: F | BN12: N | BO12: F | BP12: N | BQ12: =COUNTIF($BF12:$BP12,"E")*2+COUNTIF($BF12:$BP12,"F")*1 -> 9 | BR12: Si | BS12: Si | BT12: No | BU12: Si | BV12: Si | BW12: No | BX12: No | BY12: No | BZ12: Si | CA12: No | CB12: =COUNTIF($BR12:$CA12,"SI") -> 5 | CC12: =+BE12+BQ12+CB12 -> 29 | CD12: CATEATEN | CE12: Vnor422060 | CF12: B
A13: 2026-08 | B13: =A13&D13 -> 2026-0820537193761 | C13: =A13&"|"&G13&"|"&D13 -> 2026-08|Yeleydi|20537193761 | D13: 20537193761 | E13: FYR INTERNATIONAL GROUP S.A.C | F13: Gerencia | G13: Yeleydi | H13: 70107978 | I13: =CONCATENATE(D13,"|",G13) -> 20537193761|Yeleydi | J13: Semestral | K13: Servicios | L13: Anka | M13: Mype | N13: 500 | O13: R | P13: =IF(O13="N",0,IF(O13="A",VLOOKUP(N13,Tablas!$B$66:$D$69,2),IF(O13="R",VLOOKUP(N13,Tablas!$B$66:$D$69,3)))) -> 3 | Q13: 20 | R13: R | S13: =IF(R13="N",0,IF(R13="A",VLOOKUP(Q13,Tablas!$B$73:$D$76,2),IF(R13="R",VLOOKUP(Q13,Tablas!$B$73:$D$76,3)))) -> 1 | T13: 500 | U13: R | V13: =IF(U13="N",0,IF(U13="A",VLOOKUP(T13,Tablas!$B$80:$D$83,2),IF(U13="R",VLOOKUP(T13,Tablas!$B$80:$D$83,3)))) -> 3 | X13: N | Y13: =IF(X13="N",0,IF(X13="A",VLOOKUP(W13,Tablas!$B$87:$D$90,2),IF(X13="R",VLOOKUP(W13,Tablas!$B$87:$D$90,3)))) -> 0 | Z13: 20 | AA13: R | AB13: =IF(AA13="N",0,IF(AA13="A",VLOOKUP(Z13,Tablas!$B$143:$D$146,2),IF(AA13="R",VLOOKUP(Z13,Tablas!$B$143:$D$146,3)))) -> 1 | AC13: 4 | AD13: R | AE13: =IF(AD13="N",0,IF(AD13="A",VLOOKUP(AC13,Tablas!$B$101:$D$104,2),IF(AD13="R",VLOOKUP(AC13,Tablas!$B$101:$D$104,3)))) -> 2 | AF13: 20 | AG13: R | AH13: =IF(AG13="N",0,IF(AG13="A",VLOOKUP(AF13,Tablas!$B$94:$D$98,2),IF(AG13="R",VLOOKUP(AF13,Tablas!$B$94:$D$98,3)))) -> 1 | AI13: 50 | AJ13: R | AK13: =IF(AJ13="N",0,IF(AJ13="A",VLOOKUP(AI13,Tablas!$B$150:$D$154,2),IF(AJ13="R",VLOOKUP(AI13,Tablas!$B$150:$D$154,3)))) -> 1 | AM13: N | AN13: =IF(AM13="N",0,IF(AM13="A",VLOOKUP(AL13,Tablas!$B$108:$D$111,2),IF(AM13="R",VLOOKUP(AL13,Tablas!$B$108:$D$111,3)))) -> 0 | AP13: N | AQ13: =IF(AP13="N",0,IF(AP13="A",VLOOKUP(AO13,Tablas!$B$115:$D$118,2),IF(AP13="R",VLOOKUP(AO13,Tablas!$B$115:$D$118,3)))) -> 0 | AR13: =+W13 -> 0 | AS13: =+X13 -> N | AT13: =IF(AS13="N",0,IF(AS13="A",VLOOKUP(AR13,Tablas!$B$87:$D$90,2),IF(AS13="R",VLOOKUP(AR13,Tablas!$B$87:$D$90,3)))) -> 0 | AV13: N | AW13: =IF(AV13="N",0,IF(AV13="A",VLOOKUP(AU13,Tablas!$B$129:$D$132,2),IF(AV13="R",VLOOKUP(AU13,Tablas!$B$129:$D$132,3)))) -> 0 | AY13: N | AZ13: =IF(AY13="N",0,IF(AY13="A",VLOOKUP(AX13,Tablas!$B$136:$D$139,2),IF(AY13="R",VLOOKUP(AX13,Tablas!$B$136:$D$139,3)))) -> 0 | BB13: N | BC13: =IF(BB13="N",0,IF(BB13="A",VLOOKUP(BA13,Tablas!$B$122:$D$125,2),IF(BB13="R",VLOOKUP(BA13,Tablas!$B$122:$D$125,3)))) -> 0 | BE13: =SUMIF($N$6:$BD$6,"Valor",N13:BD13) -> 12 | BF13: E | BG13: E | BH13: F | BI13: N | BJ13: F | BK13: F | BL13: N | BM13: N | BN13: N | BO13: N | BP13: N | BQ13: =COUNTIF($BF13:$BP13,"E")*2+COUNTIF($BF13:$BP13,"F")*1 -> 7 | BR13: Si | BS13: Si | BT13: Si | BU13: No | BV13: Si | BW13: No | BX13: No | BY13: No | BZ13: No | CA13: No | CB13: =COUNTIF($BR13:$CA13,"SI") -> 4 | CC13: =+BE13+BQ13+CB13 -> 23 | CD13: TIASKING | CE13: MARIFESEO1 | CF13: C
A14: 2026-08 | B14: =A14&D14 -> 2026-0810429489372 | C14: =A14&"|"&G14&"|"&D14 -> 2026-08|Mireya|10429489372 | D14: 10429489372 | E14: GARCIA ROJAS CINDY CONSUELO | F14: Yulisa | G14: Mireya | H14: 76814749 | I14: =CONCATENATE(D14,"|",G14) -> 10429489372|Mireya | J14: Semestral | K14: Comercial | L14: Contaweb | M14: Mype | N14: 20 | O14: R | P14: =IF(O14="N",0,IF(O14="A",VLOOKUP(N14,Tablas!$B$66:$D$69,2),IF(O14="R",VLOOKUP(N14,Tablas!$B$66:$D$69,3)))) -> 1 | Q14: 20 | R14: R | S14: =IF(R14="N",0,IF(R14="A",VLOOKUP(Q14,Tablas!$B$73:$D$76,2),IF(R14="R",VLOOKUP(Q14,Tablas!$B$73:$D$76,3)))) -> 1 | T14: 100 | U14: R | V14: =IF(U14="N",0,IF(U14="A",VLOOKUP(T14,Tablas!$B$80:$D$83,2),IF(U14="R",VLOOKUP(T14,Tablas!$B$80:$D$83,3)))) -> 2 | W14: 50 | X14: R | Y14: =IF(X14="N",0,IF(X14="A",VLOOKUP(W14,Tablas!$B$87:$D$90,2),IF(X14="R",VLOOKUP(W14,Tablas!$B$87:$D$90,3)))) -> 2 | AA14: N | AB14: =IF(AA14="N",0,IF(AA14="A",VLOOKUP(Z14,Tablas!$B$143:$D$146,2),IF(AA14="R",VLOOKUP(Z14,Tablas!$B$143:$D$146,3)))) -> 0 | AC14: 2 | AD14: R | AE14: =IF(AD14="N",0,IF(AD14="A",VLOOKUP(AC14,Tablas!$B$101:$D$104,2),IF(AD14="R",VLOOKUP(AC14,Tablas!$B$101:$D$104,3)))) -> 2 | AG14: N | AH14: =IF(AG14="N",0,IF(AG14="A",VLOOKUP(AF14,Tablas!$B$94:$D$98,2),IF(AG14="R",VLOOKUP(AF14,Tablas!$B$94:$D$98,3)))) -> 0 | AJ14: N | AK14: =IF(AJ14="N",0,IF(AJ14="A",VLOOKUP(AI14,Tablas!$B$150:$D$154,2),IF(AJ14="R",VLOOKUP(AI14,Tablas!$B$150:$D$154,3)))) -> 0 | AM14: N | AN14: =IF(AM14="N",0,IF(AM14="A",VLOOKUP(AL14,Tablas!$B$108:$D$111,2),IF(AM14="R",VLOOKUP(AL14,Tablas!$B$108:$D$111,3)))) -> 0 | AP14: N | AQ14: =IF(AP14="N",0,IF(AP14="A",VLOOKUP(AO14,Tablas!$B$115:$D$118,2),IF(AP14="R",VLOOKUP(AO14,Tablas!$B$115:$D$118,3)))) -> 0 | AR14: =+W14 -> 50 | AS14: =+X14 -> R | AT14: =IF(AS14="N",0,IF(AS14="A",VLOOKUP(AR14,Tablas!$B$87:$D$90,2),IF(AS14="R",VLOOKUP(AR14,Tablas!$B$87:$D$90,3)))) -> 2 | AV14: N | AW14: =IF(AV14="N",0,IF(AV14="A",VLOOKUP(AU14,Tablas!$B$129:$D$132,2),IF(AV14="R",VLOOKUP(AU14,Tablas!$B$129:$D$132,3)))) -> 0 | AY14: N | AZ14: =IF(AY14="N",0,IF(AY14="A",VLOOKUP(AX14,Tablas!$B$136:$D$139,2),IF(AY14="R",VLOOKUP(AX14,Tablas!$B$136:$D$139,3)))) -> 0 | BB14: N | BC14: =IF(BB14="N",0,IF(BB14="A",VLOOKUP(BA14,Tablas!$B$122:$D$125,2),IF(BB14="R",VLOOKUP(BA14,Tablas!$B$122:$D$125,3)))) -> 0 | BE14: =SUMIF($N$6:$BD$6,"Valor",N14:BD14) -> 10 | BF14: E | BG14: E | BH14: N | BI14: E | BJ14: N | BK14: N | BL14: N | BM14: N | BN14: N | BO14: N | BP14: N | BQ14: =COUNTIF($BF14:$BP14,"E")*2+COUNTIF($BF14:$BP14,"F")*1 -> 6 | BR14: Si | BS14: No | BT14: No | BU14: No | BV14: No | BW14: No | BX14: No | BY14: No | BZ14: No | CA14: No | CB14: =COUNTIF($BR14:$CA14,"SI") -> 1 | CC14: =+BE14+BQ14+CB14 -> 17 | CD14: UISLONVE | CE14: ggianrang | CF14: C
A15: 2026-08 | B15: =A15&D15 -> 2026-0810468556061 | C15: =A15&"|"&G15&"|"&D15 -> 2026-08|Mireya|10468556061 | D15: 10468556061 | E15: GERONIMO ESCOBAR URSULA | F15: Yulisa | G15: Mireya | H15: 76814749 | I15: =CONCATENATE(D15,"|",G15) -> 10468556061|Mireya | J15: Mensual | K15: Servicios | L15: Contaweb | M15: Mype | N15: 3 | O15: R | P15: =IF(O15="N",0,IF(O15="A",VLOOKUP(N15,Tablas!$B$66:$D$69,2),IF(O15="R",VLOOKUP(N15,Tablas!$B$66:$D$69,3)))) -> 1 | Q15: 3 | R15: R | S15: =IF(R15="N",0,IF(R15="A",VLOOKUP(Q15,Tablas!$B$73:$D$76,2),IF(R15="R",VLOOKUP(Q15,Tablas!$B$73:$D$76,3)))) -> 1 | T15: 40 | U15: R | V15: =IF(U15="N",0,IF(U15="A",VLOOKUP(T15,Tablas!$B$80:$D$83,2),IF(U15="R",VLOOKUP(T15,Tablas!$B$80:$D$83,3)))) -> 1 | X15: N | Y15: =IF(X15="N",0,IF(X15="A",VLOOKUP(W15,Tablas!$B$87:$D$90,2),IF(X15="R",VLOOKUP(W15,Tablas!$B$87:$D$90,3)))) -> 0 | AA15: N | AB15: =IF(AA15="N",0,IF(AA15="A",VLOOKUP(Z15,Tablas!$B$143:$D$146,2),IF(AA15="R",VLOOKUP(Z15,Tablas!$B$143:$D$146,3)))) -> 0 | AC15: 2 | AD15: R | AE15: =IF(AD15="N",0,IF(AD15="A",VLOOKUP(AC15,Tablas!$B$101:$D$104,2),IF(AD15="R",VLOOKUP(AC15,Tablas!$B$101:$D$104,3)))) -> 2 | AG15: N | AH15: =IF(AG15="N",0,IF(AG15="A",VLOOKUP(AF15,Tablas!$B$94:$D$98,2),IF(AG15="R",VLOOKUP(AF15,Tablas!$B$94:$D$98,3)))) -> 0 | AI15: 20 | AJ15: R | AK15: =IF(AJ15="N",0,IF(AJ15="A",VLOOKUP(AI15,Tablas!$B$150:$D$154,2),IF(AJ15="R",VLOOKUP(AI15,Tablas!$B$150:$D$154,3)))) -> 1 | AM15: N | AN15: =IF(AM15="N",0,IF(AM15="A",VLOOKUP(AL15,Tablas!$B$108:$D$111,2),IF(AM15="R",VLOOKUP(AL15,Tablas!$B$108:$D$111,3)))) -> 0 | AP15: N | AQ15: =IF(AP15="N",0,IF(AP15="A",VLOOKUP(AO15,Tablas!$B$115:$D$118,2),IF(AP15="R",VLOOKUP(AO15,Tablas!$B$115:$D$118,3)))) -> 0 | AR15: =+W15 -> 0 | AS15: =+X15 -> N | AT15: =IF(AS15="N",0,IF(AS15="A",VLOOKUP(AR15,Tablas!$B$87:$D$90,2),IF(AS15="R",VLOOKUP(AR15,Tablas!$B$87:$D$90,3)))) -> 0 | AV15: N | AW15: =IF(AV15="N",0,IF(AV15="A",VLOOKUP(AU15,Tablas!$B$129:$D$132,2),IF(AV15="R",VLOOKUP(AU15,Tablas!$B$129:$D$132,3)))) -> 0 | AX15: 3 | AY15: R | AZ15: =IF(AY15="N",0,IF(AY15="A",VLOOKUP(AX15,Tablas!$B$136:$D$139,2),IF(AY15="R",VLOOKUP(AX15,Tablas!$B$136:$D$139,3)))) -> 1 | BB15: N | BC15: =IF(BB15="N",0,IF(BB15="A",VLOOKUP(BA15,Tablas!$B$122:$D$125,2),IF(BB15="R",VLOOKUP(BA15,Tablas!$B$122:$D$125,3)))) -> 0 | BE15: =SUMIF($N$6:$BD$6,"Valor",N15:BD15) -> 7 | BF15: F | BG15: F | BH15: N | BI15: F | BJ15: N | BK15: N | BL15: N | BM15: N | BN15: N | BO15: N | BP15: N | BQ15: =COUNTIF($BF15:$BP15,"E")*2+COUNTIF($BF15:$BP15,"F")*1 -> 3 | BR15: Si | BS15: Si | BT15: No | BU15: No | BV15: Si | BW15: No | BX15: No | BY15: No | BZ15: No | CA15: No | CB15: =COUNTIF($BR15:$CA15,"SI") -> 3 | CC15: =+BE15+BQ15+CB15 -> 13 | CD15: HAWERVAC | CE15: hrolifiel | CF15: A
A16: 2026-08 | B16: =A16&D16 -> 2026-0820605731806 | C16: =A16&"|"&G16&"|"&D16 -> 2026-08|Rocio |20605731806 | D16: 20605731806 | E16: GRUPO FINANCORP S.A.C | F16: Jose | G16: Rocio | H16: 42576958 | I16: =CONCATENATE(D16,"|",G16) -> 20605731806|Rocio | J16: Semestral | K16: Financiera | L16: Anka | M16: Mype | N16: 120 | O16: R | P16: =IF(O16="N",0,IF(O16="A",VLOOKUP(N16,Tablas!$B$66:$D$69,2),IF(O16="R",VLOOKUP(N16,Tablas!$B$66:$D$69,3)))) -> 2 | Q16: 500 | R16: A | S16: =IF(R16="N",0,IF(R16="A",VLOOKUP(Q16,Tablas!$B$73:$D$76,2),IF(R16="R",VLOOKUP(Q16,Tablas!$B$73:$D$76,3)))) -> 1.5 | T16: 3000 | U16: A | V16: =IF(U16="N",0,IF(U16="A",VLOOKUP(T16,Tablas!$B$80:$D$83,2),IF(U16="R",VLOOKUP(T16,Tablas!$B$80:$D$83,3)))) -> 2 | X16: N | Y16: =IF(X16="N",0,IF(X16="A",VLOOKUP(W16,Tablas!$B$87:$D$90,2),IF(X16="R",VLOOKUP(W16,Tablas!$B$87:$D$90,3)))) -> 0 | AA16: N | AB16: =IF(AA16="N",0,IF(AA16="A",VLOOKUP(Z16,Tablas!$B$143:$D$146,2),IF(AA16="R",VLOOKUP(Z16,Tablas!$B$143:$D$146,3)))) -> 0 | AC16: 4 | AD16: R | AE16: =IF(AD16="N",0,IF(AD16="A",VLOOKUP(AC16,Tablas!$B$101:$D$104,2),IF(AD16="R",VLOOKUP(AC16,Tablas!$B$101:$D$104,3)))) -> 2 | AF16: 8 | AG16: R | AH16: =IF(AG16="N",0,IF(AG16="A",VLOOKUP(AF16,Tablas!$B$94:$D$98,2),IF(AG16="R",VLOOKUP(AF16,Tablas!$B$94:$D$98,3)))) -> 1 | AI16: 3 | AJ16: R | AK16: =IF(AJ16="N",0,IF(AJ16="A",VLOOKUP(AI16,Tablas!$B$150:$D$154,2),IF(AJ16="R",VLOOKUP(AI16,Tablas!$B$150:$D$154,3)))) -> 1 | AM16: N | AN16: =IF(AM16="N",0,IF(AM16="A",VLOOKUP(AL16,Tablas!$B$108:$D$111,2),IF(AM16="R",VLOOKUP(AL16,Tablas!$B$108:$D$111,3)))) -> 0 | AP16: N | AQ16: =IF(AP16="N",0,IF(AP16="A",VLOOKUP(AO16,Tablas!$B$115:$D$118,2),IF(AP16="R",VLOOKUP(AO16,Tablas!$B$115:$D$118,3)))) -> 0 | AR16: =+W16 -> 0 | AS16: =+X16 -> N | AT16: =IF(AS16="N",0,IF(AS16="A",VLOOKUP(AR16,Tablas!$B$87:$D$90,2),IF(AS16="R",VLOOKUP(AR16,Tablas!$B$87:$D$90,3)))) -> 0 | AV16: N | AW16: =IF(AV16="N",0,IF(AV16="A",VLOOKUP(AU16,Tablas!$B$129:$D$132,2),IF(AV16="R",VLOOKUP(AU16,Tablas!$B$129:$D$132,3)))) -> 0 | AY16: N | AZ16: =IF(AY16="N",0,IF(AY16="A",VLOOKUP(AX16,Tablas!$B$136:$D$139,2),IF(AY16="R",VLOOKUP(AX16,Tablas!$B$136:$D$139,3)))) -> 0 | BB16: N | BC16: =IF(BB16="N",0,IF(BB16="A",VLOOKUP(BA16,Tablas!$B$122:$D$125,2),IF(BB16="R",VLOOKUP(BA16,Tablas!$B$122:$D$125,3)))) -> 0 | BE16: =SUMIF($N$6:$BD$6,"Valor",N16:BD16) -> 9.5 | BF16: E | BG16: E | BH16: N | BI16: F | BJ16: N | BK16: N | BL16: N | BM16: N | BN16: N | BO16: N | BP16: N | BQ16: =COUNTIF($BF16:$BP16,"E")*2+COUNTIF($BF16:$BP16,"F")*1 -> 5 | BR16: Si | BS16: Si | BT16: No | BU16: No | BV16: Si | BW16: No | BX16: No | BY16: No | BZ16: Si | CA16: No | CB16: =COUNTIF($BR16:$CA16,"SI") -> 4 | CC16: =+BE16+BQ16+CB16 -> 18.5 | CD16: ALISTEEK | CE16: Financorp206 | CF16: C
A17: 2026-08 | B17: =A17&D17 -> 2026-0820603904568 | C17: =A17&"|"&G17&"|"&D17 -> 2026-08|Kheilly|20603904568 | D17: 20603904568 | E17: INDUSTRIA 04 S.A.C. | F17: Omar | G17: Kheilly | H17: 70609390 | I17: =CONCATENATE(D17,"|",G17) -> 20603904568|Kheilly | J17: Mensual | K17: Servicios | L17: Anka | M17: Mype | N17: 10 | O17: A | P17: =IF(O17="N",0,IF(O17="A",VLOOKUP(N17,Tablas!$B$66:$D$69,2),IF(O17="R",VLOOKUP(N17,Tablas!$B$66:$D$69,3)))) -> 0.5 | Q17: 150 | R17: A | S17: =IF(R17="N",0,IF(R17="A",VLOOKUP(Q17,Tablas!$B$73:$D$76,2),IF(R17="R",VLOOKUP(Q17,Tablas!$B$73:$D$76,3)))) -> 1 | T17: 300 | U17: A | V17: =IF(U17="N",0,IF(U17="A",VLOOKUP(T17,Tablas!$B$80:$D$83,2),IF(U17="R",VLOOKUP(T17,Tablas!$B$80:$D$83,3)))) -> 1 | X17: N | Y17: =IF(X17="N",0,IF(X17="A",VLOOKUP(W17,Tablas!$B$87:$D$90,2),IF(X17="R",VLOOKUP(W17,Tablas!$B$87:$D$90,3)))) -> 0 | Z17: 1 | AA17: R | AB17: =IF(AA17="N",0,IF(AA17="A",VLOOKUP(Z17,Tablas!$B$143:$D$146,2),IF(AA17="R",VLOOKUP(Z17,Tablas!$B$143:$D$146,3)))) -> 1 | AC17: 10 | AD17: R | AE17: =IF(AD17="N",0,IF(AD17="A",VLOOKUP(AC17,Tablas!$B$101:$D$104,2),IF(AD17="R",VLOOKUP(AC17,Tablas!$B$101:$D$104,3)))) -> 6 | AF17: 2 | AG17: R | AH17: =IF(AG17="N",0,IF(AG17="A",VLOOKUP(AF17,Tablas!$B$94:$D$98,2),IF(AG17="R",VLOOKUP(AF17,Tablas!$B$94:$D$98,3)))) -> 1 | AI17: 2 | AJ17: R | AK17: =IF(AJ17="N",0,IF(AJ17="A",VLOOKUP(AI17,Tablas!$B$150:$D$154,2),IF(AJ17="R",VLOOKUP(AI17,Tablas!$B$150:$D$154,3)))) -> 1 | AM17: N | AN17: =IF(AM17="N",0,IF(AM17="A",VLOOKUP(AL17,Tablas!$B$108:$D$111,2),IF(AM17="R",VLOOKUP(AL17,Tablas!$B$108:$D$111,3)))) -> 0 | AP17: N | AQ17: =IF(AP17="N",0,IF(AP17="A",VLOOKUP(AO17,Tablas!$B$115:$D$118,2),IF(AP17="R",VLOOKUP(AO17,Tablas!$B$115:$D$118,3)))) -> 0 | AR17: =+W17 -> 0 | AS17: =+X17 -> N | AT17: =IF(AS17="N",0,IF(AS17="A",VLOOKUP(AR17,Tablas!$B$87:$D$90,2),IF(AS17="R",VLOOKUP(AR17,Tablas!$B$87:$D$90,3)))) -> 0 | AV17: N | AW17: =IF(AV17="N",0,IF(AV17="A",VLOOKUP(AU17,Tablas!$B$129:$D$132,2),IF(AV17="R",VLOOKUP(AU17,Tablas!$B$129:$D$132,3)))) -> 0 | AX17: 1 | AY17: R | AZ17: =IF(AY17="N",0,IF(AY17="A",VLOOKUP(AX17,Tablas!$B$136:$D$139,2),IF(AY17="R",VLOOKUP(AX17,Tablas!$B$136:$D$139,3)))) -> 1 | BB17: N | BC17: =IF(BB17="N",0,IF(BB17="A",VLOOKUP(BA17,Tablas!$B$122:$D$125,2),IF(BB17="R",VLOOKUP(BA17,Tablas!$B$122:$D$125,3)))) -> 0 | BE17: =SUMIF($N$6:$BD$6,"Valor",N17:BD17) -> 12.5 | BF17: E | BG17: E | BH17: N | BI17: F | BJ17: N | BK17: N | BL17: N | BM17: N | BN17: N | BO17: N | BP17: N | BQ17: =COUNTIF($BF17:$BP17,"E")*2+COUNTIF($BF17:$BP17,"F")*1 -> 5 | BR17: Si | BS17: Si | BT17: No | BU17: No | BV17: Si | BW17: No | BX17: No | BY17: No | BZ17: Si | CA17: No | CB17: =COUNTIF($BR17:$CA17,"SI") -> 4 | CC17: =+BE17+BQ17+CB17 -> 21.5 | CD17: REANELLE | CE17: 7LJRYjXz | CF17: A
A18: 2026-08 | B18: =A18&D18 -> 2026-0820602055834 | C18: =A18&"|"&G18&"|"&D18 -> 2026-08|Marisol|20602055834 | D18: 20602055834 | E18: INFUSIONISTA | F18: Omar | G18: Marisol | H18: 74486159 | I18: =CONCATENATE(D18,"|",G18) -> 20602055834|Marisol | J18: Mensual | K18: Bares - Restaurantes | L18: Anka | M18: General | N18: 350 | O18: R | P18: =IF(O18="N",0,IF(O18="A",VLOOKUP(N18,Tablas!$B$66:$D$69,2),IF(O18="R",VLOOKUP(N18,Tablas!$B$66:$D$69,3)))) -> 2 | Q18: 2000 | R18: R | S18: =IF(R18="N",0,IF(R18="A",VLOOKUP(Q18,Tablas!$B$73:$D$76,2),IF(R18="R",VLOOKUP(Q18,Tablas!$B$73:$D$76,3)))) -> 4 | T18: 550 | U18: R | V18: =IF(U18="N",0,IF(U18="A",VLOOKUP(T18,Tablas!$B$80:$D$83,2),IF(U18="R",VLOOKUP(T18,Tablas!$B$80:$D$83,3)))) -> 3 | X18: N | Y18: =IF(X18="N",0,IF(X18="A",VLOOKUP(W18,Tablas!$B$87:$D$90,2),IF(X18="R",VLOOKUP(W18,Tablas!$B$87:$D$90,3)))) -> 0 | Z18: 1 | AA18: R | AB18: =IF(AA18="N",0,IF(AA18="A",VLOOKUP(Z18,Tablas!$B$143:$D$146,2),IF(AA18="R",VLOOKUP(Z18,Tablas!$B$143:$D$146,3)))) -> 1 | AC18: 17 | AD18: R | AE18: =IF(AD18="N",0,IF(AD18="A",VLOOKUP(AC18,Tablas!$B$101:$D$104,2),IF(AD18="R",VLOOKUP(AC18,Tablas!$B$101:$D$104,3)))) -> 6 | AF18: 25 | AG18: R | AH18: =IF(AG18="N",0,IF(AG18="A",VLOOKUP(AF18,Tablas!$B$94:$D$98,2),IF(AG18="R",VLOOKUP(AF18,Tablas!$B$94:$D$98,3)))) -> 1 | AI18: 1 | AJ18: N | AK18: =IF(AJ18="N",0,IF(AJ18="A",VLOOKUP(AI18,Tablas!$B$150:$D$154,2),IF(AJ18="R",VLOOKUP(AI18,Tablas!$B$150:$D$154,3)))) -> 0 | AM18: N | AN18: =IF(AM18="N",0,IF(AM18="A",VLOOKUP(AL18,Tablas!$B$108:$D$111,2),IF(AM18="R",VLOOKUP(AL18,Tablas!$B$108:$D$111,3)))) -> 0 | AP18: N | AQ18: =IF(AP18="N",0,IF(AP18="A",VLOOKUP(AO18,Tablas!$B$115:$D$118,2),IF(AP18="R",VLOOKUP(AO18,Tablas!$B$115:$D$118,3)))) -> 0 | AR18: 12 | AS18: R | AT18: =IF(AS18="N",0,IF(AS18="A",VLOOKUP(AR18,Tablas!$B$87:$D$90,2),IF(AS18="R",VLOOKUP(AR18,Tablas!$B$87:$D$90,3)))) -> 2 | AV18: N | AW18: =IF(AV18="N",0,IF(AV18="A",VLOOKUP(AU18,Tablas!$B$129:$D$132,2),IF(AV18="R",VLOOKUP(AU18,Tablas!$B$129:$D$132,3)))) -> 0 | AY18: N | AZ18: =IF(AY18="N",0,IF(AY18="A",VLOOKUP(AX18,Tablas!$B$136:$D$139,2),IF(AY18="R",VLOOKUP(AX18,Tablas!$B$136:$D$139,3)))) -> 0 | BB18: N | BC18: =IF(BB18="N",0,IF(BB18="A",VLOOKUP(BA18,Tablas!$B$122:$D$125,2),IF(BB18="R",VLOOKUP(BA18,Tablas!$B$122:$D$125,3)))) -> 0 | BE18: =SUMIF($N$6:$BD$6,"Valor",N18:BD18) -> 19 | BF18: E | BG18: E | BH18: F | BI18: N | BJ18: F | BK18: N | BL18: N | BM18: N | BN18: N | BO18: N | BP18: N | BQ18: =COUNTIF($BF18:$BP18,"E")*2+COUNTIF($BF18:$BP18,"F")*1 -> 6 | BR18: Si | BS18: Si | BT18: No | BU18: No | BV18: Si | BW18: No | BX18: No | BY18: No | BZ18: No | CA18: No | CB18: =COUNTIF($BR18:$CA18,"SI") -> 3 | CC18: =+BE18+BQ18+CB18 -> 28 | CD18: TIONEFUL | CE18: rnadestan | CF18: A
A19: 2026-08 | B19: =A19&D19 -> 2026-0820510760795 | C19: =A19&"|"&G19&"|"&D19 -> 2026-08|Kheilly|20510760795 | D19: 20510760795 | E19: INVERSIONES CAMPO VERDE S.A.C. | F19: Omar | G19: Kheilly | H19: 70609390 | I19: =CONCATENATE(D19,"|",G19) -> 20510760795|Kheilly | J19: Trimestral | K19: Comercial | L19: Anka | M19: Mype | N19: 50 | O19: A | P19: =IF(O19="N",0,IF(O19="A",VLOOKUP(N19,Tablas!$B$66:$D$69,2),IF(O19="R",VLOOKUP(N19,Tablas!$B$66:$D$69,3)))) -> 0.5 | Q19: 50 | R19: A | S19: =IF(R19="N",0,IF(R19="A",VLOOKUP(Q19,Tablas!$B$73:$D$76,2),IF(R19="R",VLOOKUP(Q19,Tablas!$B$73:$D$76,3)))) -> 0.5 | T19: 250 | U19: A | V19: =IF(U19="N",0,IF(U19="A",VLOOKUP(T19,Tablas!$B$80:$D$83,2),IF(U19="R",VLOOKUP(T19,Tablas!$B$80:$D$83,3)))) -> 1 | W19: 50 | X19: A | Y19: =IF(X19="N",0,IF(X19="A",VLOOKUP(W19,Tablas!$B$87:$D$90,2),IF(X19="R",VLOOKUP(W19,Tablas!$B$87:$D$90,3)))) -> 1 | Z19: 1 | AA19: A | AB19: =IF(AA19="N",0,IF(AA19="A",VLOOKUP(Z19,Tablas!$B$143:$D$146,2),IF(AA19="R",VLOOKUP(Z19,Tablas!$B$143:$D$146,3)))) -> 0.5 | AC19: 1 | AD19: A | AE19: =IF(AD19="N",0,IF(AD19="A",VLOOKUP(AC19,Tablas!$B$101:$D$104,2),IF(AD19="R",VLOOKUP(AC19,Tablas!$B$101:$D$104,3)))) -> 1 | AF19: 25 | AG19: A | AH19: =IF(AG19="N",0,IF(AG19="A",VLOOKUP(AF19,Tablas!$B$94:$D$98,2),IF(AG19="R",VLOOKUP(AF19,Tablas!$B$94:$D$98,3)))) -> 0.5 | AI19: 1 | AJ19: A | AK19: =IF(AJ19="N",0,IF(AJ19="A",VLOOKUP(AI19,Tablas!$B$150:$D$154,2),IF(AJ19="R",VLOOKUP(AI19,Tablas!$B$150:$D$154,3)))) -> 0.5 | AM19: N | AN19: =IF(AM19="N",0,IF(AM19="A",VLOOKUP(AL19,Tablas!$B$108:$D$111,2),IF(AM19="R",VLOOKUP(AL19,Tablas!$B$108:$D$111,3)))) -> 0 | AO19: 1 | AP19: A | AQ19: =IF(AP19="N",0,IF(AP19="A",VLOOKUP(AO19,Tablas!$B$115:$D$118,2),IF(AP19="R",VLOOKUP(AO19,Tablas!$B$115:$D$118,3)))) -> 0.5 | AR19: =+W19 -> 50 | AS19: =+X19 -> A | AT19: =IF(AS19="N",0,IF(AS19="A",VLOOKUP(AR19,Tablas!$B$87:$D$90,2),IF(AS19="R",VLOOKUP(AR19,Tablas!$B$87:$D$90,3)))) -> 1 | AV19: N | AW19: =IF(AV19="N",0,IF(AV19="A",VLOOKUP(AU19,Tablas!$B$129:$D$132,2),IF(AV19="R",VLOOKUP(AU19,Tablas!$B$129:$D$132,3)))) -> 0 | AY19: N | AZ19: =IF(AY19="N",0,IF(AY19="A",VLOOKUP(AX19,Tablas!$B$136:$D$139,2),IF(AY19="R",VLOOKUP(AX19,Tablas!$B$136:$D$139,3)))) -> 0 | BA19: 10 | BB19: A | BC19: =IF(BB19="N",0,IF(BB19="A",VLOOKUP(BA19,Tablas!$B$122:$D$125,2),IF(BB19="R",VLOOKUP(BA19,Tablas!$B$122:$D$125,3)))) -> 1 | BE19: =SUMIF($N$6:$BD$6,"Valor",N19:BD19) -> 8 | BF19: E | BG19: E | BH19: F | BI19: N | BJ19: F | BK19: F | BL19: N | BM19: F | BN19: N | BO19: F | BP19: N | BQ19: =COUNTIF($BF19:$BP19,"E")*2+COUNTIF($BF19:$BP19,"F")*1 -> 9 | BR19: Si | BS19: Si | BT19: Si | BU19: No | BV19: Si | BW19: No | BX19: No | BY19: Si | BZ19: Si | CA19: No | CB19: =COUNTIF($BR19:$CA19,"SI") -> 6 | CC19: =+BE19+BQ19+CB19 -> 23 | CD19: SILVIAAA | CE19: SILVIAAA | CF19: B
A20: 2026-08 | B20: =A20&D20 -> 2026-0820608557971 | C20: =A20&"|"&G20&"|"&D20 -> 2026-08|Mireya|20608557971 | D20: 20608557971 | E20: JIMZU SPIRIT E.I.R.L. | F20: Yulisa | G20: Mireya | H20: 76814749 | I20: =CONCATENATE(D20,"|",G20) -> 20608557971|Mireya | J20: Semestral | K20: Servicios | L20: Contaweb | M20: Rer | N20: 20 | O20: R | P20: =IF(O20="N",0,IF(O20="A",VLOOKUP(N20,Tablas!$B$66:$D$69,2),IF(O20="R",VLOOKUP(N20,Tablas!$B$66:$D$69,3)))) -> 1 | Q20: 17 | R20: R | S20: =IF(R20="N",0,IF(R20="A",VLOOKUP(Q20,Tablas!$B$73:$D$76,2),IF(R20="R",VLOOKUP(Q20,Tablas!$B$73:$D$76,3)))) -> 1 | U20: N | V20: =IF(U20="N",0,IF(U20="A",VLOOKUP(T20,Tablas!$B$80:$D$83,2),IF(U20="R",VLOOKUP(T20,Tablas!$B$80:$D$83,3)))) -> 0 | X20: N | Y20: =IF(X20="N",0,IF(X20="A",VLOOKUP(W20,Tablas!$B$87:$D$90,2),IF(X20="R",VLOOKUP(W20,Tablas!$B$87:$D$90,3)))) -> 0 | AA20: N | AB20: =IF(AA20="N",0,IF(AA20="A",VLOOKUP(Z20,Tablas!$B$143:$D$146,2),IF(AA20="R",VLOOKUP(Z20,Tablas!$B$143:$D$146,3)))) -> 0 | AD20: N | AE20: =IF(AD20="N",0,IF(AD20="A",VLOOKUP(AC20,Tablas!$B$101:$D$104,2),IF(AD20="R",VLOOKUP(AC20,Tablas!$B$101:$D$104,3)))) -> 0 | AG20: N | AH20: =IF(AG20="N",0,IF(AG20="A",VLOOKUP(AF20,Tablas!$B$94:$D$98,2),IF(AG20="R",VLOOKUP(AF20,Tablas!$B$94:$D$98,3)))) -> 0 | AJ20: N | AK20: =IF(AJ20="N",0,IF(AJ20="A",VLOOKUP(AI20,Tablas!$B$150:$D$154,2),IF(AJ20="R",VLOOKUP(AI20,Tablas!$B$150:$D$154,3)))) -> 0 | AM20: N | AN20: =IF(AM20="N",0,IF(AM20="A",VLOOKUP(AL20,Tablas!$B$108:$D$111,2),IF(AM20="R",VLOOKUP(AL20,Tablas!$B$108:$D$111,3)))) -> 0 | AP20: N | AQ20: =IF(AP20="N",0,IF(AP20="A",VLOOKUP(AO20,Tablas!$B$115:$D$118,2),IF(AP20="R",VLOOKUP(AO20,Tablas!$B$115:$D$118,3)))) -> 0 | AR20: =+W20 -> 0 | AS20: =+X20 -> N | AT20: =IF(AS20="N",0,IF(AS20="A",VLOOKUP(AR20,Tablas!$B$87:$D$90,2),IF(AS20="R",VLOOKUP(AR20,Tablas!$B$87:$D$90,3)))) -> 0 | AV20: N | AW20: =IF(AV20="N",0,IF(AV20="A",VLOOKUP(AU20,Tablas!$B$129:$D$132,2),IF(AV20="R",VLOOKUP(AU20,Tablas!$B$129:$D$132,3)))) -> 0 | AY20: N | AZ20: =IF(AY20="N",0,IF(AY20="A",VLOOKUP(AX20,Tablas!$B$136:$D$139,2),IF(AY20="R",VLOOKUP(AX20,Tablas!$B$136:$D$139,3)))) -> 0 | BB20: N | BC20: =IF(BB20="N",0,IF(BB20="A",VLOOKUP(BA20,Tablas!$B$122:$D$125,2),IF(BB20="R",VLOOKUP(BA20,Tablas!$B$122:$D$125,3)))) -> 0 | BE20: =SUMIF($N$6:$BD$6,"Valor",N20:BD20) -> 2 | BF20: E | BG20: E | BH20: N | BI20: N | BJ20: N | BK20: N | BL20: N | BM20: N | BN20: N | BO20: N | BP20: N | BQ20: =COUNTIF($BF20:$BP20,"E")*2+COUNTIF($BF20:$BP20,"F")*1 -> 4 | BR20: Si | BS20: No | BT20: No | BU20: No | BV20: No | BW20: No | BX20: No | BY20: No | BZ20: No | CA20: No | CB20: =COUNTIF($BR20:$CA20,"SI") -> 1 | CC20: =+BE20+BQ20+CB20 -> 7 | CD20: 72077895 | CE20: Jose3564044 | CF20: D
A21: 2026-08 | B21: =A21&D21 -> 2026-0820607296813 | C21: =A21&"|"&G21&"|"&D21 -> 2026-08|Rocio |20607296813 | D21: 20607296813 | E21: JVL IMPORT & EXPORT GROUP S.A.C. | F21: Jose | G21: Rocio | H21: 42576958 | I21: =CONCATENATE(D21,"|",G21) -> 20607296813|Rocio | J21: Semestral | K21: Comercial | L21: Contaweb | M21: Mype | N21: 40 | O21: R | P21: =IF(O21="N",0,IF(O21="A",VLOOKUP(N21,Tablas!$B$66:$D$69,2),IF(O21="R",VLOOKUP(N21,Tablas!$B$66:$D$69,3)))) -> 1 | Q21: 150 | R21: R | S21: =IF(R21="N",0,IF(R21="A",VLOOKUP(Q21,Tablas!$B$73:$D$76,2),IF(R21="R",VLOOKUP(Q21,Tablas!$B$73:$D$76,3)))) -> 2 | T21: 120 | U21: R | V21: =IF(U21="N",0,IF(U21="A",VLOOKUP(T21,Tablas!$B$80:$D$83,2),IF(U21="R",VLOOKUP(T21,Tablas!$B$80:$D$83,3)))) -> 2 | W21: 250 | X21: R | Y21: =IF(X21="N",0,IF(X21="A",VLOOKUP(W21,Tablas!$B$87:$D$90,2),IF(X21="R",VLOOKUP(W21,Tablas!$B$87:$D$90,3)))) -> 4 | AA21: N | AB21: =IF(AA21="N",0,IF(AA21="A",VLOOKUP(Z21,Tablas!$B$143:$D$146,2),IF(AA21="R",VLOOKUP(Z21,Tablas!$B$143:$D$146,3)))) -> 0 | AC21: 4 | AD21: R | AE21: =IF(AD21="N",0,IF(AD21="A",VLOOKUP(AC21,Tablas!$B$101:$D$104,2),IF(AD21="R",VLOOKUP(AC21,Tablas!$B$101:$D$104,3)))) -> 2 | AG21: N | AH21: =IF(AG21="N",0,IF(AG21="A",VLOOKUP(AF21,Tablas!$B$94:$D$98,2),IF(AG21="R",VLOOKUP(AF21,Tablas!$B$94:$D$98,3)))) -> 0 | AJ21: N | AK21: =IF(AJ21="N",0,IF(AJ21="A",VLOOKUP(AI21,Tablas!$B$150:$D$154,2),IF(AJ21="R",VLOOKUP(AI21,Tablas!$B$150:$D$154,3)))) -> 0 | AL21: 2 | AM21: R | AN21: =IF(AM21="N",0,IF(AM21="A",VLOOKUP(AL21,Tablas!$B$108:$D$111,2),IF(AM21="R",VLOOKUP(AL21,Tablas!$B$108:$D$111,3)))) -> 4 | AP21: N | AQ21: =IF(AP21="N",0,IF(AP21="A",VLOOKUP(AO21,Tablas!$B$115:$D$118,2),IF(AP21="R",VLOOKUP(AO21,Tablas!$B$115:$D$118,3)))) -> 0 | AR21: =+W21 -> 250 | AS21: =+X21 -> R | AT21: =IF(AS21="N",0,IF(AS21="A",VLOOKUP(AR21,Tablas!$B$87:$D$90,2),IF(AS21="R",VLOOKUP(AR21,Tablas!$B$87:$D$90,3)))) -> 4 | AV21: N | AW21: =IF(AV21="N",0,IF(AV21="A",VLOOKUP(AU21,Tablas!$B$129:$D$132,2),IF(AV21="R",VLOOKUP(AU21,Tablas!$B$129:$D$132,3)))) -> 0 | AY21: N | AZ21: =IF(AY21="N",0,IF(AY21="A",VLOOKUP(AX21,Tablas!$B$136:$D$139,2),IF(AY21="R",VLOOKUP(AX21,Tablas!$B$136:$D$139,3)))) -> 0 | BB21: N | BC21: =IF(BB21="N",0,IF(BB21="A",VLOOKUP(BA21,Tablas!$B$122:$D$125,2),IF(BB21="R",VLOOKUP(BA21,Tablas!$B$122:$D$125,3)))) -> 0 | BE21: =SUMIF($N$6:$BD$6,"Valor",N21:BD21) -> 19 | BF21: E | BG21: E | BH21: N | BI21: F | BJ21: N | BK21: N | BL21: N | BM21: N | BN21: N | BO21: N | BP21: N | BQ21: =COUNTIF($BF21:$BP21,"E")*2+COUNTIF($BF21:$BP21,"F")*1 -> 5 | BR21: Si | BS21: Si | BT21: No | BU21: No | BV21: Si | BW21: No | BX21: No | BY21: No | BZ21: Si | CA21: No | CB21: =COUNTIF($BR21:$CA21,"SI") -> 4 | CC21: =+BE21+BQ21+CB21 -> 28 | CD21: 70236049 | CE21: 70236049Vera | CF21: C
A22: 2026-08 | B22: =A22&D22 -> 2026-0820602118798 | C22: =A22&"|"&G22&"|"&D22 -> 2026-08|Rocio |20602118798 | D22: 20602118798 | E22: MARCTEX S.A.C. | F22: Jose | G22: Rocio | H22: 42576958 | I22: =CONCATENATE(D22,"|",G22) -> 20602118798|Rocio | J22: Semestral | K22: Comercial | L22: Contaweb | M22: Mype | N22: 80 | O22: R | P22: =IF(O22="N",0,IF(O22="A",VLOOKUP(N22,Tablas!$B$66:$D$69,2),IF(O22="R",VLOOKUP(N22,Tablas!$B$66:$D$69,3)))) -> 1 | Q22: 25 | R22: R | S22: =IF(R22="N",0,IF(R22="A",VLOOKUP(Q22,Tablas!$B$73:$D$76,2),IF(R22="R",VLOOKUP(Q22,Tablas!$B$73:$D$76,3)))) -> 1 | T22: 60 | U22: R | V22: =IF(U22="N",0,IF(U22="A",VLOOKUP(T22,Tablas!$B$80:$D$83,2),IF(U22="R",VLOOKUP(T22,Tablas!$B$80:$D$83,3)))) -> 1 | W22: 300 | X22: R | Y22: =IF(X22="N",0,IF(X22="A",VLOOKUP(W22,Tablas!$B$87:$D$90,2),IF(X22="R",VLOOKUP(W22,Tablas!$B$87:$D$90,3)))) -> 4 | AA22: N | AB22: =IF(AA22="N",0,IF(AA22="A",VLOOKUP(Z22,Tablas!$B$143:$D$146,2),IF(AA22="R",VLOOKUP(Z22,Tablas!$B$143:$D$146,3)))) -> 0 | AC22: 4 | AD22: R | AE22: =IF(AD22="N",0,IF(AD22="A",VLOOKUP(AC22,Tablas!$B$101:$D$104,2),IF(AD22="R",VLOOKUP(AC22,Tablas!$B$101:$D$104,3)))) -> 2 | AG22: N | AH22: =IF(AG22="N",0,IF(AG22="A",VLOOKUP(AF22,Tablas!$B$94:$D$98,2),IF(AG22="R",VLOOKUP(AF22,Tablas!$B$94:$D$98,3)))) -> 0 | AJ22: N | AK22: =IF(AJ22="N",0,IF(AJ22="A",VLOOKUP(AI22,Tablas!$B$150:$D$154,2),IF(AJ22="R",VLOOKUP(AI22,Tablas!$B$150:$D$154,3)))) -> 0 | AL22: 4 | AM22: R | AN22: =IF(AM22="N",0,IF(AM22="A",VLOOKUP(AL22,Tablas!$B$108:$D$111,2),IF(AM22="R",VLOOKUP(AL22,Tablas!$B$108:$D$111,3)))) -> 4 | AP22: N | AQ22: =IF(AP22="N",0,IF(AP22="A",VLOOKUP(AO22,Tablas!$B$115:$D$118,2),IF(AP22="R",VLOOKUP(AO22,Tablas!$B$115:$D$118,3)))) -> 0 | AR22: =+W22 -> 300 | AS22: =+X22 -> R | AT22: =IF(AS22="N",0,IF(AS22="A",VLOOKUP(AR22,Tablas!$B$87:$D$90,2),IF(AS22="R",VLOOKUP(AR22,Tablas!$B$87:$D$90,3)))) -> 4 | AV22: N | AW22: =IF(AV22="N",0,IF(AV22="A",VLOOKUP(AU22,Tablas!$B$129:$D$132,2),IF(AV22="R",VLOOKUP(AU22,Tablas!$B$129:$D$132,3)))) -> 0 | AY22: N | AZ22: =IF(AY22="N",0,IF(AY22="A",VLOOKUP(AX22,Tablas!$B$136:$D$139,2),IF(AY22="R",VLOOKUP(AX22,Tablas!$B$136:$D$139,3)))) -> 0 | BB22: N | BC22: =IF(BB22="N",0,IF(BB22="A",VLOOKUP(BA22,Tablas!$B$122:$D$125,2),IF(BB22="R",VLOOKUP(BA22,Tablas!$B$122:$D$125,3)))) -> 0 | BE22: =SUMIF($N$6:$BD$6,"Valor",N22:BD22) -> 17 | BF22: F | BG22: F | BH22: N | BI22: F | BJ22: N | BK22: N | BL22: N | BM22: N | BN22: N | BO22: N | BP22: N | BQ22: =COUNTIF($BF22:$BP22,"E")*2+COUNTIF($BF22:$BP22,"F")*1 -> 3 | BR22: Si | BS22: Si | BT22: No | BU22: No | BV22: Si | BW22: No | BX22: No | BY22: No | BZ22: Si | CA22: No | CB22: =COUNTIF($BR22:$CA22,"SI") -> 4 | CC22: =+BE22+BQ22+CB22 -> 24 | CD22: AZIUMPAR | CE22: viianswor | CF22: D
A23: 2026-08 | B23: =A23&D23 -> 2026-0820601293413 | C23: =A23&"|"&G23&"|"&D23 -> 2026-08|Jhony|20601293413 | D23: 20601293413 | E23: NEGOCIOS SAN AGUSTIN S.A.C. | F23: Omar | G23: Jhony | H23: 71594822 | I23: =CONCATENATE(D23,"|",G23) -> 20601293413|Jhony | J23: Semestral | K23: Comercial | L23: Contaweb | M23: Rer | N23: 120 | O23: R | P23: =IF(O23="N",0,IF(O23="A",VLOOKUP(N23,Tablas!$B$66:$D$69,2),IF(O23="R",VLOOKUP(N23,Tablas!$B$66:$D$69,3)))) -> 2 | Q23: 75 | R23: R | S23: =IF(R23="N",0,IF(R23="A",VLOOKUP(Q23,Tablas!$B$73:$D$76,2),IF(R23="R",VLOOKUP(Q23,Tablas!$B$73:$D$76,3)))) -> 1 | U23: N | V23: =IF(U23="N",0,IF(U23="A",VLOOKUP(T23,Tablas!$B$80:$D$83,2),IF(U23="R",VLOOKUP(T23,Tablas!$B$80:$D$83,3)))) -> 0 | X23: N | Y23: =IF(X23="N",0,IF(X23="A",VLOOKUP(W23,Tablas!$B$87:$D$90,2),IF(X23="R",VLOOKUP(W23,Tablas!$B$87:$D$90,3)))) -> 0 | AA23: N | AB23: =IF(AA23="N",0,IF(AA23="A",VLOOKUP(Z23,Tablas!$B$143:$D$146,2),IF(AA23="R",VLOOKUP(Z23,Tablas!$B$143:$D$146,3)))) -> 0 | AC23: 3 | AD23: R | AE23: =IF(AD23="N",0,IF(AD23="A",VLOOKUP(AC23,Tablas!$B$101:$D$104,2),IF(AD23="R",VLOOKUP(AC23,Tablas!$B$101:$D$104,3)))) -> 2 | AG23: N | AH23: =IF(AG23="N",0,IF(AG23="A",VLOOKUP(AF23,Tablas!$B$94:$D$98,2),IF(AG23="R",VLOOKUP(AF23,Tablas!$B$94:$D$98,3)))) -> 0 | AJ23: N | AK23: =IF(AJ23="N",0,IF(AJ23="A",VLOOKUP(AI23,Tablas!$B$150:$D$154,2),IF(AJ23="R",VLOOKUP(AI23,Tablas!$B$150:$D$154,3)))) -> 0 | AM23: N | AN23: =IF(AM23="N",0,IF(AM23="A",VLOOKUP(AL23,Tablas!$B$108:$D$111,2),IF(AM23="R",VLOOKUP(AL23,Tablas!$B$108:$D$111,3)))) -> 0 | AP23: N | AQ23: =IF(AP23="N",0,IF(AP23="A",VLOOKUP(AO23,Tablas!$B$115:$D$118,2),IF(AP23="R",VLOOKUP(AO23,Tablas!$B$115:$D$118,3)))) -> 0 | AR23: =+W23 -> 0 | AS23: =+X23 -> N | AT23: =IF(AS23="N",0,IF(AS23="A",VLOOKUP(AR23,Tablas!$B$87:$D$90,2),IF(AS23="R",VLOOKUP(AR23,Tablas!$B$87:$D$90,3)))) -> 0 | AV23: N | AW23: =IF(AV23="N",0,IF(AV23="A",VLOOKUP(AU23,Tablas!$B$129:$D$132,2),IF(AV23="R",VLOOKUP(AU23,Tablas!$B$129:$D$132,3)))) -> 0 | AY23: N | AZ23: =IF(AY23="N",0,IF(AY23="A",VLOOKUP(AX23,Tablas!$B$136:$D$139,2),IF(AY23="R",VLOOKUP(AX23,Tablas!$B$136:$D$139,3)))) -> 0 | BB23: N | BC23: =IF(BB23="N",0,IF(BB23="A",VLOOKUP(BA23,Tablas!$B$122:$D$125,2),IF(BB23="R",VLOOKUP(BA23,Tablas!$B$122:$D$125,3)))) -> 0 | BE23: =SUMIF($N$6:$BD$6,"Valor",N23:BD23) -> 5 | BF23: F | BG23: F | BH23: N | BI23: N | BJ23: N | BK23: N | BL23: N | BM23: N | BN23: N | BO23: N | BP23: N | BQ23: =COUNTIF($BF23:$BP23,"E")*2+COUNTIF($BF23:$BP23,"F")*1 -> 2 | BR23: Si | BS23: Si | BT23: No | BU23: No | BV23: Si | BW23: No | BX23: No | BY23: No | BZ23: No | CA23: No | CB23: =COUNTIF($BR23:$CA23,"SI") -> 3 | CC23: =+BE23+BQ23+CB23 -> 10 | CD23: OOMPAUTL | CE23: inerentra | CF23: D
A24: 2026-08 | B24: =A24&D24 -> 2026-0820605578528 | C24: =A24&"|"&G24&"|"&D24 -> 2026-08|Rocio |20605578528 | D24: 20605578528 | E24: PERU INDUSTRI GN S.A.C. | F24: Jose | G24: Rocio | H24: 42576958 | I24: =CONCATENATE(D24,"|",G24) -> 20605578528|Rocio | J24: Semestral | K24: Comercial | L24: Contaweb | M24: Mype | N24: 30 | O24: A | P24: =IF(O24="N",0,IF(O24="A",VLOOKUP(N24,Tablas!$B$66:$D$69,2),IF(O24="R",VLOOKUP(N24,Tablas!$B$66:$D$69,3)))) -> 0.5 | Q24: 2 | R24: A | S24: =IF(R24="N",0,IF(R24="A",VLOOKUP(Q24,Tablas!$B$73:$D$76,2),IF(R24="R",VLOOKUP(Q24,Tablas!$B$73:$D$76,3)))) -> 0.5 | T24: =4*25*2 -> 200 | U24: A | V24: =IF(U24="N",0,IF(U24="A",VLOOKUP(T24,Tablas!$B$80:$D$83,2),IF(U24="R",VLOOKUP(T24,Tablas!$B$80:$D$83,3)))) -> 1 | W24: 100 | X24: A | Y24: =IF(X24="N",0,IF(X24="A",VLOOKUP(W24,Tablas!$B$87:$D$90,2),IF(X24="R",VLOOKUP(W24,Tablas!$B$87:$D$90,3)))) -> 2 | AA24: N | AB24: =IF(AA24="N",0,IF(AA24="A",VLOOKUP(Z24,Tablas!$B$143:$D$146,2),IF(AA24="R",VLOOKUP(Z24,Tablas!$B$143:$D$146,3)))) -> 0 | AD24: N | AE24: =IF(AD24="N",0,IF(AD24="A",VLOOKUP(AC24,Tablas!$B$101:$D$104,2),IF(AD24="R",VLOOKUP(AC24,Tablas!$B$101:$D$104,3)))) -> 0 | AF24: 20 | AG24: A | AH24: =IF(AG24="N",0,IF(AG24="A",VLOOKUP(AF24,Tablas!$B$94:$D$98,2),IF(AG24="R",VLOOKUP(AF24,Tablas!$B$94:$D$98,3)))) -> 0.5 | AI24: 20 | AJ24: R | AK24: =IF(AJ24="N",0,IF(AJ24="A",VLOOKUP(AI24,Tablas!$B$150:$D$154,2),IF(AJ24="R",VLOOKUP(AI24,Tablas!$B$150:$D$154,3)))) -> 1 | AM24: N | AN24: =IF(AM24="N",0,IF(AM24="A",VLOOKUP(AL24,Tablas!$B$108:$D$111,2),IF(AM24="R",VLOOKUP(AL24,Tablas!$B$108:$D$111,3)))) -> 0 | AO24: 3 | AP24: R | AQ24: =IF(AP24="N",0,IF(AP24="A",VLOOKUP(AO24,Tablas!$B$115:$D$118,2),IF(AP24="R",VLOOKUP(AO24,Tablas!$B$115:$D$118,3)))) -> 2 | AR24: =+W24 -> 100 | AS24: =+X24 -> A | AT24: =IF(AS24="N",0,IF(AS24="A",VLOOKUP(AR24,Tablas!$B$87:$D$90,2),IF(AS24="R",VLOOKUP(AR24,Tablas!$B$87:$D$90,3)))) -> 2 | AV24: N | AW24: =IF(AV24="N",0,IF(AV24="A",VLOOKUP(AU24,Tablas!$B$129:$D$132,2),IF(AV24="R",VLOOKUP(AU24,Tablas!$B$129:$D$132,3)))) -> 0 | AY24: N | AZ24: =IF(AY24="N",0,IF(AY24="A",VLOOKUP(AX24,Tablas!$B$136:$D$139,2),IF(AY24="R",VLOOKUP(AX24,Tablas!$B$136:$D$139,3)))) -> 0 | BA24: 1 | BB24: A | BC24: =IF(BB24="N",0,IF(BB24="A",VLOOKUP(BA24,Tablas!$B$122:$D$125,2),IF(BB24="R",VLOOKUP(BA24,Tablas!$B$122:$D$125,3)))) -> 1 | BE24: =SUMIF($N$6:$BD$6,"Valor",N24:BD24) -> 10.5 | BF24: E | BG24: E | BH24: F | BI24: N | BJ24: F | BK24: F | BL24: N | BM24: N | BN24: N | BO24: N | BP24: N | BQ24: =COUNTIF($BF24:$BP24,"E")*2+COUNTIF($BF24:$BP24,"F")*1 -> 7 | BR24: Si | BS24: No | BT24: No | BU24: Si | BV24: No | BW24: No | BX24: No | BY24: No | BZ24: Si | CA24: No | CB24: =COUNTIF($BR24:$CA24,"SI") -> 3 | CC24: =+BE24+BQ24+CB24 -> 20.5 | CD24: UREADALL | CE24: bantantsw | CF24: C
A25: 2026-08 | B25: =A25&D25 -> 2026-0820609054604 | C25: =A25&"|"&G25&"|"&D25 -> 2026-08|Mireya|20609054604 | D25: 20609054604 | E25: FULL CARGO SAC | F25: Yulisa | G25: Mireya | H25: 76814749 | I25: =CONCATENATE(D25,"|",G25) -> 20609054604|Mireya | J25: Semestral | K25: Servicios | L25: Contaweb | M25: Mype | N25: 60 | O25: R | P25: =IF(O25="N",0,IF(O25="A",VLOOKUP(N25,Tablas!$B$66:$D$69,2),IF(O25="R",VLOOKUP(N25,Tablas!$B$66:$D$69,3)))) -> 1 | Q25: 40 | R25: R | S25: =IF(R25="N",0,IF(R25="A",VLOOKUP(Q25,Tablas!$B$73:$D$76,2),IF(R25="R",VLOOKUP(Q25,Tablas!$B$73:$D$76,3)))) -> 1 | T25: 60 | U25: R | V25: =IF(U25="N",0,IF(U25="A",VLOOKUP(T25,Tablas!$B$80:$D$83,2),IF(U25="R",VLOOKUP(T25,Tablas!$B$80:$D$83,3)))) -> 1 | X25: N | Y25: =IF(X25="N",0,IF(X25="A",VLOOKUP(W25,Tablas!$B$87:$D$90,2),IF(X25="R",VLOOKUP(W25,Tablas!$B$87:$D$90,3)))) -> 0 | AA25: N | AB25: =IF(AA25="N",0,IF(AA25="A",VLOOKUP(Z25,Tablas!$B$143:$D$146,2),IF(AA25="R",VLOOKUP(Z25,Tablas!$B$143:$D$146,3)))) -> 0 | AC25: 1 | AD25: R | AE25: =IF(AD25="N",0,IF(AD25="A",VLOOKUP(AC25,Tablas!$B$101:$D$104,2),IF(AD25="R",VLOOKUP(AC25,Tablas!$B$101:$D$104,3)))) -> 2 | AG25: N | AH25: =IF(AG25="N",0,IF(AG25="A",VLOOKUP(AF25,Tablas!$B$94:$D$98,2),IF(AG25="R",VLOOKUP(AF25,Tablas!$B$94:$D$98,3)))) -> 0 | AI25: 1 | AJ25: R | AK25: =IF(AJ25="N",0,IF(AJ25="A",VLOOKUP(AI25,Tablas!$B$150:$D$154,2),IF(AJ25="R",VLOOKUP(AI25,Tablas!$B$150:$D$154,3)))) -> 1 | AM25: N | AN25: =IF(AM25="N",0,IF(AM25="A",VLOOKUP(AL25,Tablas!$B$108:$D$111,2),IF(AM25="R",VLOOKUP(AL25,Tablas!$B$108:$D$111,3)))) -> 0 | AP25: N | AQ25: =IF(AP25="N",0,IF(AP25="A",VLOOKUP(AO25,Tablas!$B$115:$D$118,2),IF(AP25="R",VLOOKUP(AO25,Tablas!$B$115:$D$118,3)))) -> 0 | AR25: =+W25 -> 0 | AS25: =+X25 -> N | AT25: =IF(AS25="N",0,IF(AS25="A",VLOOKUP(AR25,Tablas!$B$87:$D$90,2),IF(AS25="R",VLOOKUP(AR25,Tablas!$B$87:$D$90,3)))) -> 0 | AV25: N | AW25: =IF(AV25="N",0,IF(AV25="A",VLOOKUP(AU25,Tablas!$B$129:$D$132,2),IF(AV25="R",VLOOKUP(AU25,Tablas!$B$129:$D$132,3)))) -> 0 | AX25: 1 | AY25: R | AZ25: =IF(AY25="N",0,IF(AY25="A",VLOOKUP(AX25,Tablas!$B$136:$D$139,2),IF(AY25="R",VLOOKUP(AX25,Tablas!$B$136:$D$139,3)))) -> 1 | BB25: N | BC25: =IF(BB25="N",0,IF(BB25="A",VLOOKUP(BA25,Tablas!$B$122:$D$125,2),IF(BB25="R",VLOOKUP(BA25,Tablas!$B$122:$D$125,3)))) -> 0 | BE25: =SUMIF($N$6:$BD$6,"Valor",N25:BD25) -> 7 | BF25: E | BG25: E | BH25: N | BI25: F | BJ25: N | BK25: N | BL25: N | BM25: N | BN25: N | BO25: N | BP25: N | BQ25: =COUNTIF($BF25:$BP25,"E")*2+COUNTIF($BF25:$BP25,"F")*1 -> 5 | BR25: Si | BS25: Si | BT25: No | BU25: No | BV25: Si | BW25: No | BX25: No | BY25: No | BZ25: No | CA25: No | CB25: =COUNTIF($BR25:$CA25,"SI") -> 3 | CC25: =+BE25+BQ25+CB25 -> 15 | CD25: 40850688 | CE25: Full40850688 | CF25: C
